Workbook

Sheet RAW_HNSCC_METADATA_NEW_v11
A1: ID | B1: Type of Visit | C1: Diagnosis | D1: OGID | E1: cfDNA Isolation Date | F1: WGS Library Prep Date | G1: Date of Diagnosis | H1: Date of Consent | I1: Neoadj Pembro | J1: Surgery Date | K1: Radiation Start | L1: Radiation End | M1: Wk1 pembro | N1: Date off Treatment | O1: Withdrawal Date | P1: OLD Last Known Alive | Q1: Last known alive | R1: OLD Date of Recurrence | S1: Date of Recurrence | T1: OLD Date of Death | U1: Date of Death | V1: OLD E_Relapse | W1: E_Relapse | X1: OLD E_Survival | Y1: E_Survival | Z1: OLD Relapse Months (Neoadjuvant) | AA1: Relapse Months (Neoadjuvant) | AB1: OLD Survival Months (Neoadjuvant) | AC1: Survival Months (Neoadjuvant) | AD1: OLD Relapse Months (Surgery) | AE1: Relapse Months (Surgery) | AF1: OLD Survival Months (Surgery) | AG1: Survival Months (Surgery) | AH1: OLD Relapse Months (Adjuvant) | AI1: Relapse Months (Adjuvant) | AJ1: OLD Survival Months (Adjuvant) | AK1: Survival Months (Adjuvant) | AL1: Pilot | AM1: Institute | AN1: Physician Hold-Out | AO1: Patient Number | AP1: Age | AQ1: Gender | AR1: Race | AS1: Smoking | AT1: Ethnicity | AU1: Alcohol | AV1: TNM | AW1: Stratification | AX1: HPV | AY1: PDL1 IHC | AZ1: Response Rate Categorized | BA1: Response Rate Real | BB1: Treatment Response | BC1: cfDNA Concentration (ng/uL) | BD1: Plasma Collection Date | BE1: cfDNA Volume (uL) | BF1: Need Volume (uL) | BG1: Add Low TE | BH1: WGS library concentration (10cycles, ng/uL) | BI1: Pool Volume | BJ1: Index | BK1: i7 | BL1: i5
A2: Pilot2_3 | B2: =VLOOKUP(A2, IDSLOOKUP!C:E, 2, FALSE) -> Screen | C2: =VLOOKUP(D2, METADATALOOKUP!$A:$AI, 13, FALSE) -> Oral Cavity | D2: =VLOOKUP(A2, IDSLOOKUP!C:E, 3, FALSE) -> HN01-37 | E2: =VLOOKUP(A2,CFDNALOOKUP!AG:AI,2,FALSE) -> 44090 | F2: =VLOOKUP(A2,CFDNALOOKUP!AG:AI,3,FALSE) -> 44179 | G2: =VLOOKUP(D2, SURVLOOKUP!$A:$Q, 2, FALSE) -> 43514 | H2: =VLOOKUP(D2, SURVLOOKUP!$A:$Q, 3, FALSE) -> 43531 | I2: =VLOOKUP(D2, SURVLOOKUP!$A:$Q, 4, FALSE) -> 43535 | J2: =VLOOKUP(D2, SURVLOOKUP!$A:$Q, 5, FALSE) -> 43542 | K2: =VLOOKUP(D2, SURVLOOKUP!$A:$Q, 6, FALSE) -> 43586 | L2: =VLOOKUP(D2, SURVLOOKUP!$A:$Q, 7, FALSE) -> 43628 | M2: =VLOOKUP(D2, SURVLOOKUP!$A:$Q, 8, FALSE) -> 43581 | N2: =VLOOKUP(D2, SURVLOOKUP!$A:$Q, 9, FALSE) -> 43683 | O2: =VLOOKUP(D2, SURVLOOKUP!$A:$Q, 10, FALSE) -> NA | P2: =VLOOKUP(D2, OLDSURVLOOKUP!$A:$AA, 19, FALSE) -> 44130 | Q2: =VLOOKUP(D2, SURVLOOKUP!$A:$Q, 11, FALSE) -> 44130 | R2: =VLOOKUP(D2, OLDSURVLOOKUP!$A:$AA, 20, FALSE) -> 43899 | S2: =VLOOKUP(D2, SURVLOOKUP!$A:$Q, 12, FALSE) -> 43899 | T2: =VLOOKUP(D2, OLDSURVLOOKUP!$A:$AA, 21, FALSE) -> 44131 | U2: =VLOOKUP(D2, SURVLOOKUP!$A:$Q, 13, FALSE) -> 44131 | V2: =_xlfn.XLOOKUP(D2, OLDSURVLOOKUP!$A:$A, OLDSURVLOOKUP!V:V) -> 1 | W2: =VLOOKUP(D2, SURVLOOKUP!$A:$Q, 14, FALSE) -> 1 | X2: =_xlfn.XLOOKUP(D2, OLDSURVLOOKUP!$A:$A, OLDSURVLOOKUP!X:X) -> 1 | Y2: =VLOOKUP(D2, SURVLOOKUP!$A:$Q, 15, FALSE) -> 1 | Z2: =IF(V2=0, DATEDIF(I2,P2,"M")+DATEDIF(I2,P2,"MD")/DAY(EOMONTH(I2,0)), DATEDIF(I2,R2,"M")+DATEDIF(I2,R2,"MD")/DAY(EOMONTH(I2,0))) -> 11.870968 | AA2: =IF(W2=0, DATEDIF(I2,Q2,"M")+DATEDIF(I2,Q2,"MD")/DAY(EOMONTH(I2,0)), DATEDIF(I2,S2,"M")+DATEDIF(I2,S2,"MD")/DAY(EOMONTH(I2,0))) -> 11.870968 | AB2: =IF(X2=0, DATEDIF(I2,P2,"M")+DATEDIF(I2,P2,"MD")/DAY(EOMONTH(I2,0)), DATEDIF(I2,T2,"M")+DATEDIF(I2,T2,"MD")/DAY(EOMONTH(I2,0))) -> 19.516129 | AC2: =IF(Y2=0, DATEDIF(I2,Q2,"M")+DATEDIF(I2,Q2,"MD")/DAY(EOMONTH(I2,0)), DATEDIF(I2,U2,"M")+DATEDIF(I2,U2,"MD")/DAY(EOMONTH(I2,0))) -> 19.516129 | AD2: =IF(V2=0, DATEDIF(J2,P2,"M")+DATEDIF(J2,P2,"MD")/DAY(EOMONTH(J2,0)), DATEDIF(J2,R2,"M")+DATEDIF(J2,R2,"MD")/DAY(EOMONTH(J2,0))) -> 11.645161 | AE2: =IF(W2=0, DATEDIF(J2,Q2,"M")+DATEDIF(J2,Q2,"MD")/DAY(EOMONTH(J2,0)), DATEDIF(J2,S2,"M")+DATEDIF(J2,S2,"MD")/DAY(EOMONTH(J2,0))) -> 11.645161 | AF2: =IF(X2=0, DATEDIF(J2,P2,"M")+DATEDIF(J2,P2,"MD")/DAY(EOMONTH(J2,0)), DATEDIF(J2,T2,"M")+DATEDIF(J2,T2,"MD")/DAY(EOMONTH(J2,0))) -> 19.290323 | AG2: =IF(Y2=0, DATEDIF(J2,Q2,"M")+DATEDIF(J2,Q2,"MD")/DAY(EOMONTH(J2,0)), DATEDIF(J2,U2,"M")+DATEDIF(J2,U2,"MD")/DAY(EOMONTH(J2,0))) -> 19.290323 | AH2: =IF(V2=0, DATEDIF(M2,P2,"M")+DATEDIF(M2,P2,"MD")/DAY(EOMONTH(M2,0)), DATEDIF(M2,R2,"M")+DATEDIF(M2,R2,"MD")/DAY(EOMONTH(M2,0))) -> 10.4 | AI2: =IF(W2=0, DATEDIF(M2,Q2,"M")+DATEDIF(M2,Q2,"MD")/DAY(EOMONTH(M2,0)), DATEDIF(M2,S2,"M")+DATEDIF(M2,S2,"MD")/DAY(EOMONTH(M2,0))) -> 10.4 | AJ2: =IF(X2=0, DATEDIF(M2,P2,"M")+DATEDIF(M2,P2,"MD")/DAY(EOMONTH(M2,0)), DATEDIF(M2,T2,"M")+DATEDIF(M2,T2,"MD")/DAY(EOMONTH(M2,0))) -> 18.033333 | AK2: =IF(Y2=0, DATEDIF(M2,Q2,"M")+DATEDIF(M2,Q2,"MD")/DAY(EOMONTH(M2,0)), DATEDIF(M2,U2,"M")+DATEDIF(M2,U2,"MD")/DAY(EOMONTH(M2,0))) -> 18.033333 | AL2: =IF(MID(A2,FIND("_",A2)-1,1)="2", 2, 1) -> 2 | AM2: =IFERROR( CHOOSE( VALUE(MID(D2, FIND("-", D2) - 1, 1)), "University of Cincinnati", "Ohio State University", "Medical University of South Carolina", "University of Michigan", "University of Louisville", "MD Anderson" ), "Unknown" ) -> University of Cincinnati | AN2: 0 | AO2: 1 | AP2: =VLOOKUP(D2, METADATALOOKUP!$A:$AI, 7, FALSE) -> 44 | AQ2: =VLOOKUP(D2, METADATALOOKUP!$A:$AI, 8, FALSE) -> Female | AR2: =VLOOKUP(D2, METADATALOOKUP!$A:$AI, 9, FALSE) -> White | AS2: =VLOOKUP(D2, METADATALOOKUP!$A:$AI, 11, FALSE) -> Yes | AT2: =VLOOKUP(D2, METADATALOOKUP!$A:$AI, 10, FALSE) -> Non-Hispanic | AU2: =VLOOKUP(D2, METADATALOOKUP!$A:$AI, 12, FALSE) -> No | AV2: =VLOOKUP(D2, METADATALOOKUP!$A:$AI, 14, FALSE) -> T3N2cM0 | AW2: =VLOOKUP(D2, METADATALOOKUP!$A:$AI, 6, FALSE) -> High | AX2: =VLOOKUP(D2, METADATALOOKUP!$A:$AI, 19, FALSE) -> Unknown | AY2: =LOOKUP(D2, SURVLOOKUP!$A:$A, SURVLOOKUP!$P:$P) -> 1 | AZ2: 0 | BA2: =TEXT(VLOOKUP(D2, METADATALOOKUP!$A:$AI, 34, FALSE), "@") -> <10% | BB2: =IF(AZ2=0, "Non-Responder", "Responder") -> Non-Responder | BC2: 0.05 | BE2: 24 | BF2: 15 | BG2: 35 | BH2: 16.6 | BI2: 1.506024 | BJ2: UDI0213 | BK2: AAGCAGAC | BL2: GCTAAGAA
A3: Pilot2_4 | B3: =VLOOKUP(A3, IDSLOOKUP!C:E, 2, FALSE) -> Day 0 | C3: =VLOOKUP(D3, METADATALOOKUP!$A:$AI, 13, FALSE) -> Oral Cavity | D3: =VLOOKUP(A3, IDSLOOKUP!C:E, 3, FALSE) -> HN01-37 | E3: =VLOOKUP(A3,CFDNALOOKUP!AG:AI,2,FALSE) -> 44090 | F3: =VLOOKUP(A3,CFDNALOOKUP!AG:AI,3,FALSE) -> 44180 | G3: =VLOOKUP(D3, SURVLOOKUP!$A:$Q, 2, FALSE) -> 43514 | H3: =VLOOKUP(D3, SURVLOOKUP!$A:$Q, 3, FALSE) -> 43531 | I3: =VLOOKUP(D3, SURVLOOKUP!$A:$Q, 4, FALSE) -> 43535 | J3: =VLOOKUP(D3, SURVLOOKUP!$A:$Q, 5, FALSE) -> 43542 | K3: =VLOOKUP(D3, SURVLOOKUP!$A:$Q, 6, FALSE) -> 43586 | L3: =VLOOKUP(D3, SURVLOOKUP!$A:$Q, 7, FALSE) -> 43628 | M3: =VLOOKUP(D3, SURVLOOKUP!$A:$Q, 8, FALSE) -> 43581 | N3: =VLOOKUP(D3, SURVLOOKUP!$A:$Q, 9, FALSE) -> 43683 | O3: =VLOOKUP(D3, SURVLOOKUP!$A:$Q, 10, FALSE) -> NA | P3: =VLOOKUP(D3, OLDSURVLOOKUP!$A:$AA, 19, FALSE) -> 44130 | Q3: =VLOOKUP(D3, SURVLOOKUP!$A:$Q, 11, FALSE) -> 44130 | R3: =VLOOKUP(D3, OLDSURVLOOKUP!$A:$AA, 20, FALSE) -> 43899 | S3: =VLOOKUP(D3, SURVLOOKUP!$A:$Q, 12, FALSE) -> 43899 | T3: =VLOOKUP(D3, OLDSURVLOOKUP!$A:$AA, 21, FALSE) -> 44131 | U3: =VLOOKUP(D3, SURVLOOKUP!$A:$Q, 13, FALSE) -> 44131 | V3: =_xlfn.XLOOKUP(D3, OLDSURVLOOKUP!$A:$A, OLDSURVLOOKUP!V:V) -> 1 | W3: =VLOOKUP(D3, SURVLOOKUP!$A:$Q, 14, FALSE) -> 1 | X3: =_xlfn.XLOOKUP(D3, OLDSURVLOOKUP!$A:$A, OLDSURVLOOKUP!X:X) -> 1 | Y3: =VLOOKUP(D3, SURVLOOKUP!$A:$Q, 15, FALSE) -> 1 | Z3: =IF(V3=0, DATEDIF(I3,P3,"M")+DATEDIF(I3,P3,"MD")/DAY(EOMONTH(I3,0)), DATEDIF(I3,R3,"M")+DATEDIF(I3,R3,"MD")/DAY(EOMONTH(I3,0))) -> 11.870968 | AA3: =IF(W3=0, DATEDIF(I3,Q3,"M")+DATEDIF(I3,Q3,"MD")/DAY(EOMONTH(I3,0)), DATEDIF(I3,S3,"M")+DATEDIF(I3,S3,"MD")/DAY(EOMONTH(I3,0))) -> 11.870968 | AB3: =IF(X3=0, DATEDIF(I3,P3,"M")+DATEDIF(I3,P3,"MD")/DAY(EOMONTH(I3,0)), DATEDIF(I3,T3,"M")+DATEDIF(I3,T3,"MD")/DAY(EOMONTH(I3,0))) -> 19.516129 | AC3: =IF(Y3=0, DATEDIF(I3,Q3,"M")+DATEDIF(I3,Q3,"MD")/DAY(EOMONTH(I3,0)), DATEDIF(I3,U3,"M")+DATEDIF(I3,U3,"MD")/DAY(EOMONTH(I3,0))) -> 19.516129 | AD3: =IF(V3=0, DATEDIF(J3,P3,"M")+DATEDIF(J3,P3,"MD")/DAY(EOMONTH(J3,0)), DATEDIF(J3,R3,"M")+DATEDIF(J3,R3,"MD")/DAY(EOMONTH(J3,0))) -> 11.645161 | AE3: =IF(W3=0, DATEDIF(J3,Q3,"M")+DATEDIF(J3,Q3,"MD")/DAY(EOMONTH(J3,0)), DATEDIF(J3,S3,"M")+DATEDIF(J3,S3,"MD")/DAY(EOMONTH(J3,0))) -> 11.645161 | AF3: =IF(X3=0, DATEDIF(J3,P3,"M")+DATEDIF(J3,P3,"MD")/DAY(EOMONTH(J3,0)), DATEDIF(J3,T3,"M")+DATEDIF(J3,T3,"MD")/DAY(EOMONTH(J3,0))) -> 19.290323 | AG3: =IF(Y3=0, DATEDIF(J3,Q3,"M")+DATEDIF(J3,Q3,"MD")/DAY(EOMONTH(J3,0)), DATEDIF(J3,U3,"M")+DATEDIF(J3,U3,"MD")/DAY(EOMONTH(J3,0))) -> 19.290323 | AH3: =IF(V3=0, DATEDIF(M3,P3,"M")+DATEDIF(M3,P3,"MD")/DAY(EOMONTH(M3,0)), DATEDIF(M3,R3,"M")+DATEDIF(M3,R3,"MD")/DAY(EOMONTH(M3,0))) -> 10.4 | AI3: =IF(W3=0, DATEDIF(M3,Q3,"M")+DATEDIF(M3,Q3,"MD")/DAY(EOMONTH(M3,0)), DATEDIF(M3,S3,"M")+DATEDIF(M3,S3,"MD")/DAY(EOMONTH(M3,0))) -> 10.4 | AJ3: =IF(X3=0, DATEDIF(M3,P3,"M")+DATEDIF(M3,P3,"MD")/DAY(EOMONTH(M3,0)), DATEDIF(M3,T3,"M")+DATEDIF(M3,T3,"MD")/DAY(EOMONTH(M3,0))) -> 18.033333 | AK3: =IF(Y3=0, DATEDIF(M3,Q3,"M")+DATEDIF(M3,Q3,"MD")/DAY(EOMONTH(M3,0)), DATEDIF(M3,U3,"M")+DATEDIF(M3,U3,"MD")/DAY(EOMONTH(M3,0))) -> 18.033333 | AL3: =IF(MID(A3,FIND("_",A3)-1,1)="2", 2, 1) -> 2 | AM3: =IFERROR( CHOOSE( VALUE(MID(D3, FIND("-", D3) - 1, 1)), "University of Cincinnati", "Ohio State University", "Medical University of South Carolina", "University of Michigan", "University of Louisville", "MD Anderson" ), "Unknown" ) -> University of Cincinnati | AN3: 0 | AO3: 1 | AP3: =VLOOKUP(D3, METADATALOOKUP!$A:$AI, 7, FALSE) -> 44 | AQ3: =VLOOKUP(D3, METADATALOOKUP!$A:$AI, 8, FALSE) -> Female | AR3: =VLOOKUP(D3, METADATALOOKUP!$A:$AI, 9, FALSE) -> White | AS3: =VLOOKUP(D3, METADATALOOKUP!$A:$AI, 11, FALSE) -> Yes | AT3: =VLOOKUP(D3, METADATALOOKUP!$A:$AI, 10, FALSE) -> Non-Hispanic | AU3: =VLOOKUP(D3, METADATALOOKUP!$A:$AI, 12, FALSE) -> No | AV3: =VLOOKUP(D3, METADATALOOKUP!$A:$AI, 14, FALSE) -> T3N2cM0 | AW3: =VLOOKUP(D3, METADATALOOKUP!$A:$AI, 6, FALSE) -> High | AX3: =VLOOKUP(D3, METADATALOOKUP!$A:$AI, 19, FALSE) -> Unknown | AY3: =LOOKUP(D3, SURVLOOKUP!$A:$A, SURVLOOKUP!$P:$P) -> 1 | AZ3: 0 | BA3: =TEXT(VLOOKUP(D3, METADATALOOKUP!$A:$AI, 34, FALSE), "@") -> <10% | BB3: =IF(AZ3=0, "Non-Responder", "Responder") -> Non-Responder | BC3: 0.464 | BE3: 24 | BF3: 2.155172 | BG3: 47.84483 | BH3: 11 | BI3: 2.272727 | BJ3: UDI0267 | BK3: GCAAGACA | BL3: GCATAGAC
A4: Pilot2_5 | B4: =VLOOKUP(A4, IDSLOOKUP!C:E, 2, FALSE) -> Adj Wk 1 | C4: =VLOOKUP(D4, METADATALOOKUP!$A:$AI, 13, FALSE) -> Oral Cavity | D4: =VLOOKUP(A4, IDSLOOKUP!C:E, 3, FALSE) -> HN01-37 | E4: =VLOOKUP(A4,CFDNALOOKUP!AG:AI,2,FALSE) -> 44090 | F4: =VLOOKUP(A4,CFDNALOOKUP!AG:AI,3,FALSE) -> 44179 | G4: =VLOOKUP(D4, SURVLOOKUP!$A:$Q, 2, FALSE) -> 43514 | H4: =VLOOKUP(D4, SURVLOOKUP!$A:$Q, 3, FALSE) -> 43531 | I4: =VLOOKUP(D4, SURVLOOKUP!$A:$Q, 4, FALSE) -> 43535 | J4: =VLOOKUP(D4, SURVLOOKUP!$A:$Q, 5, FALSE) -> 43542 | K4: =VLOOKUP(D4, SURVLOOKUP!$A:$Q, 6, FALSE) -> 43586 | L4: =VLOOKUP(D4, SURVLOOKUP!$A:$Q, 7, FALSE) -> 43628 | M4: =VLOOKUP(D4, SURVLOOKUP!$A:$Q, 8, FALSE) -> 43581 | N4: =VLOOKUP(D4, SURVLOOKUP!$A:$Q, 9, FALSE) -> 43683 | O4: =VLOOKUP(D4, SURVLOOKUP!$A:$Q, 10, FALSE) -> NA | P4: =VLOOKUP(D4, OLDSURVLOOKUP!$A:$AA, 19, FALSE) -> 44130 | Q4: =VLOOKUP(D4, SURVLOOKUP!$A:$Q, 11, FALSE) -> 44130 | R4: =VLOOKUP(D4, OLDSURVLOOKUP!$A:$AA, 20, FALSE) -> 43899 | S4: =VLOOKUP(D4, SURVLOOKUP!$A:$Q, 12, FALSE) -> 43899 | T4: =VLOOKUP(D4, OLDSURVLOOKUP!$A:$AA, 21, FALSE) -> 44131 | U4: =VLOOKUP(D4, SURVLOOKUP!$A:$Q, 13, FALSE) -> 44131 | V4: =_xlfn.XLOOKUP(D4, OLDSURVLOOKUP!$A:$A, OLDSURVLOOKUP!V:V) -> 1 | W4: =VLOOKUP(D4, SURVLOOKUP!$A:$Q, 14, FALSE) -> 1 | X4: =_xlfn.XLOOKUP(D4, OLDSURVLOOKUP!$A:$A, OLDSURVLOOKUP!X:X) -> 1 | Y4: =VLOOKUP(D4, SURVLOOKUP!$A:$Q, 15, FALSE) -> 1 | Z4: =IF(V4=0, DATEDIF(I4,P4,"M")+DATEDIF(I4,P4,"MD")/DAY(EOMONTH(I4,0)), DATEDIF(I4,R4,"M")+DATEDIF(I4,R4,"MD")/DAY(EOMONTH(I4,0))) -> 11.870968 | AA4: =IF(W4=0, DATEDIF(I4,Q4,"M")+DATEDIF(I4,Q4,"MD")/DAY(EOMONTH(I4,0)), DATEDIF(I4,S4,"M")+DATEDIF(I4,S4,"MD")/DAY(EOMONTH(I4,0))) -> 11.870968 | AB4: =IF(X4=0, DATEDIF(I4,P4,"M")+DATEDIF(I4,P4,"MD")/DAY(EOMONTH(I4,0)), DATEDIF(I4,T4,"M")+DATEDIF(I4,T4,"MD")/DAY(EOMONTH(I4,0))) -> 19.516129 | AC4: =IF(Y4=0, DATEDIF(I4,Q4,"M")+DATEDIF(I4,Q4,"MD")/DAY(EOMONTH(I4,0)), DATEDIF(I4,U4,"M")+DATEDIF(I4,U4,"MD")/DAY(EOMONTH(I4,0))) -> 19.516129 | AD4: =IF(V4=0, DATEDIF(J4,P4,"M")+DATEDIF(J4,P4,"MD")/DAY(EOMONTH(J4,0)), DATEDIF(J4,R4,"M")+DATEDIF(J4,R4,"MD")/DAY(EOMONTH(J4,0))) -> 11.645161 | AE4: =IF(W4=0, DATEDIF(J4,Q4,"M")+DATEDIF(J4,Q4,"MD")/DAY(EOMONTH(J4,0)), DATEDIF(J4,S4,"M")+DATEDIF(J4,S4,"MD")/DAY(EOMONTH(J4,0))) -> 11.645161 | AF4: =IF(X4=0, DATEDIF(J4,P4,"M")+DATEDIF(J4,P4,"MD")/DAY(EOMONTH(J4,0)), DATEDIF(J4,T4,"M")+DATEDIF(J4,T4,"MD")/DAY(EOMONTH(J4,0))) -> 19.290323 | AG4: =IF(Y4=0, DATEDIF(J4,Q4,"M")+DATEDIF(J4,Q4,"MD")/DAY(EOMONTH(J4,0)), DATEDIF(J4,U4,"M")+DATEDIF(J4,U4,"MD")/DAY(EOMONTH(J4,0))) -> 19.290323 | AH4: =IF(V4=0, DATEDIF(M4,P4,"M")+DATEDIF(M4,P4,"MD")/DAY(EOMONTH(M4,0)), DATEDIF(M4,R4,"M")+DATEDIF(M4,R4,"MD")/DAY(EOMONTH(M4,0))) -> 10.4 | AI4: =IF(W4=0, DATEDIF(M4,Q4,"M")+DATEDIF(M4,Q4,"MD")/DAY(EOMONTH(M4,0)), DATEDIF(M4,S4,"M")+DATEDIF(M4,S4,"MD")/DAY(EOMONTH(M4,0))) -> 10.4 | AJ4: =IF(X4=0, DATEDIF(M4,P4,"M")+DATEDIF(M4,P4,"MD")/DAY(EOMONTH(M4,0)), DATEDIF(M4,T4,"M")+DATEDIF(M4,T4,"MD")/DAY(EOMONTH(M4,0))) -> 18.033333 | AK4: =IF(Y4=0, DATEDIF(M4,Q4,"M")+DATEDIF(M4,Q4,"MD")/DAY(EOMONTH(M4,0)), DATEDIF(M4,U4,"M")+DATEDIF(M4,U4,"MD")/DAY(EOMONTH(M4,0))) -> 18.033333 | AL4: =IF(MID(A4,FIND("_",A4)-1,1)="2", 2, 1) -> 2 | AM4: =IFERROR( CHOOSE( VALUE(MID(D4, FIND("-", D4) - 1, 1)), "University of Cincinnati", "Ohio State University", "Medical University of South Carolina", "University of Michigan", "University of Louisville", "MD Anderson" ), "Unknown" ) -> University of Cincinnati | AN4: 0 | AO4: 1 | AP4: =VLOOKUP(D4, METADATALOOKUP!$A:$AI, 7, FALSE) -> 44 | AQ4: =VLOOKUP(D4, METADATALOOKUP!$A:$AI, 8, FALSE) -> Female | AR4: =VLOOKUP(D4, METADATALOOKUP!$A:$AI, 9, FALSE) -> White | AS4: =VLOOKUP(D4, METADATALOOKUP!$A:$AI, 11, FALSE) -> Yes | AT4: =VLOOKUP(D4, METADATALOOKUP!$A:$AI, 10, FALSE) -> Non-Hispanic | AU4: =VLOOKUP(D4, METADATALOOKUP!$A:$AI, 12, FALSE) -> No | AV4: =VLOOKUP(D4, METADATALOOKUP!$A:$AI, 14, FALSE) -> T3N2cM0 | AW4: =VLOOKUP(D4, METADATALOOKUP!$A:$AI, 6, FALSE) -> High | AX4: =VLOOKUP(D4, METADATALOOKUP!$A:$AI, 19, FALSE) -> Unknown | AY4: =LOOKUP(D4, SURVLOOKUP!$A:$A, SURVLOOKUP!$P:$P) -> 1 | AZ4: 0 | BA4: =TEXT(VLOOKUP(D4, METADATALOOKUP!$A:$AI, 34, FALSE), "@") -> <10% | BB4: =IF(AZ4=0, "Non-Responder", "Responder") -> Non-Responder | BC4: 0.2 | BE4: 24 | BF4: 5 | BG4: 45 | BH4: 12.2 | BI4: 2.04918 | BJ4: UDI0254 | BK4: TCTCCGTG | BL4: TGAATCGT
A5: Pilot2_6 | B5: =VLOOKUP(A5, IDSLOOKUP!C:E, 2, FALSE) -> Screen | C5: =VLOOKUP(D5, METADATALOOKUP!$A:$AI, 13, FALSE) -> Oral Cavity | D5: =VLOOKUP(A5, IDSLOOKUP!C:E, 3, FALSE) -> HN01-49 | E5: =VLOOKUP(A5,CFDNALOOKUP!AG:AI,2,FALSE) -> 44090 | F5: =VLOOKUP(A5,CFDNALOOKUP!AG:AI,3,FALSE) -> 44180 | G5: =VLOOKUP(D5, SURVLOOKUP!$A:$Q, 2, FALSE) -> 43656 | H5: =VLOOKUP(D5, SURVLOOKUP!$A:$Q, 3, FALSE) -> 43977 | I5: =VLOOKUP(D5, SURVLOOKUP!$A:$Q, 4, FALSE) -> 43994 | J5: =VLOOKUP(D5, SURVLOOKUP!$A:$Q, 5, FALSE) -> 44012 | K5: =VLOOKUP(D5, SURVLOOKUP!$A:$Q, 6, FALSE) -> NA | L5: =VLOOKUP(D5, SURVLOOKUP!$A:$Q, 7, FALSE) -> NA | M5: =VLOOKUP(D5, SURVLOOKUP!$A:$Q, 8, FALSE) -> 44061 | N5: =VLOOKUP(D5, SURVLOOKUP!$A:$Q, 9, FALSE) -> 44105 | O5: =VLOOKUP(D5, SURVLOOKUP!$A:$Q, 10, FALSE) -> NA | P5: =VLOOKUP(D5, OLDSURVLOOKUP!$A:$AA, 19, FALSE) -> 44159 | Q5: =VLOOKUP(D5, SURVLOOKUP!$A:$Q, 11, FALSE) -> 44159 | R5: =VLOOKUP(D5, OLDSURVLOOKUP!$A:$AA, 20, FALSE) -> 44106 | S5: =VLOOKUP(D5, SURVLOOKUP!$A:$Q, 12, FALSE) -> 44106 | T5: =VLOOKUP(D5, OLDSURVLOOKUP!$A:$AA, 21, FALSE) -> 44160 | U5: =VLOOKUP(D5, SURVLOOKUP!$A:$Q, 13, FALSE) -> 44160 | V5: =_xlfn.XLOOKUP(D5, OLDSURVLOOKUP!$A:$A, OLDSURVLOOKUP!V:V) -> 1 | W5: =VLOOKUP(D5, SURVLOOKUP!$A:$Q, 14, FALSE) -> 1 | X5: =_xlfn.XLOOKUP(D5, OLDSURVLOOKUP!$A:$A, OLDSURVLOOKUP!X:X) -> 1 | Y5: =VLOOKUP(D5, SURVLOOKUP!$A:$Q, 15, FALSE) -> 1 | Z5: =IF(V5=0, DATEDIF(I5,P5,"M")+DATEDIF(I5,P5,"MD")/DAY(EOMONTH(I5,0)), DATEDIF(I5,R5,"M")+DATEDIF(I5,R5,"MD")/DAY(EOMONTH(I5,0))) -> 3.6666667 | AA5: =IF(W5=0, DATEDIF(I5,Q5,"M")+DATEDIF(I5,Q5,"MD")/DAY(EOMONTH(I5,0)), DATEDIF(I5,S5,"M")+DATEDIF(I5,S5,"MD")/DAY(EOMONTH(I5,0))) -> 3.6666667 | AB5: =IF(X5=0, DATEDIF(I5,P5,"M")+DATEDIF(I5,P5,"MD")/DAY(EOMONTH(I5,0)), DATEDIF(I5,T5,"M")+DATEDIF(I5,T5,"MD")/DAY(EOMONTH(I5,0))) -> 5.4333333 | AC5: =IF(Y5=0, DATEDIF(I5,Q5,"M")+DATEDIF(I5,Q5,"MD")/DAY(EOMONTH(I5,0)), DATEDIF(I5,U5,"M")+DATEDIF(I5,U5,"MD")/DAY(EOMONTH(I5,0))) -> 5.4333333 | AD5: =IF(V5=0, DATEDIF(J5,P5,"M")+DATEDIF(J5,P5,"MD")/DAY(EOMONTH(J5,0)), DATEDIF(J5,R5,"M")+DATEDIF(J5,R5,"MD")/DAY(EOMONTH(J5,0))) -> 3.0666667 | AE5: =IF(W5=0, DATEDIF(J5,Q5,"M")+DATEDIF(J5,Q5,"MD")/DAY(EOMONTH(J5,0)), DATEDIF(J5,S5,"M")+DATEDIF(J5,S5,"MD")/DAY(EOMONTH(J5,0))) -> 3.0666667 | AF5: =IF(X5=0, DATEDIF(J5,P5,"M")+DATEDIF(J5,P5,"MD")/DAY(EOMONTH(J5,0)), DATEDIF(J5,T5,"M")+DATEDIF(J5,T5,"MD")/DAY(EOMONTH(J5,0))) -> 4.8666667 | AG5: =IF(Y5=0, DATEDIF(J5,Q5,"M")+DATEDIF(J5,Q5,"MD")/DAY(EOMONTH(J5,0)), DATEDIF(J5,U5,"M")+DATEDIF(J5,U5,"MD")/DAY(EOMONTH(J5,0))) -> 4.8666667 | AH5: =IF(V5=0, DATEDIF(M5,P5,"M")+DATEDIF(M5,P5,"MD")/DAY(EOMONTH(M5,0)), DATEDIF(M5,R5,"M")+DATEDIF(M5,R5,"MD")/DAY(EOMONTH(M5,0))) -> 1.4516129 | AI5: =IF(W5=0, DATEDIF(M5,Q5,"M")+DATEDIF(M5,Q5,"MD")/DAY(EOMONTH(M5,0)), DATEDIF(M5,S5,"M")+DATEDIF(M5,S5,"MD")/DAY(EOMONTH(M5,0))) -> 1.4516129 | AJ5: =IF(X5=0, DATEDIF(M5,P5,"M")+DATEDIF(M5,P5,"MD")/DAY(EOMONTH(M5,0)), DATEDIF(M5,T5,"M")+DATEDIF(M5,T5,"MD")/DAY(EOMONTH(M5,0))) -> 3.2258065 | AK5: =IF(Y5=0, DATEDIF(M5,Q5,"M")+DATEDIF(M5,Q5,"MD")/DAY(EOMONTH(M5,0)), DATEDIF(M5,U5,"M")+DATEDIF(M5,U5,"MD")/DAY(EOMONTH(M5,0))) -> 3.2258065 | AL5: =IF(MID(A5,FIND("_",A5)-1,1)="2", 2, 1) -> 2 | AM5: =IFERROR( CHOOSE( VALUE(MID(D5, FIND("-", D5) - 1, 1)), "University of Cincinnati", "Ohio State University", "Medical University of South Carolina", "University of Michigan", "University of Louisville", "MD Anderson" ), "Unknown" ) -> University of Cincinnati | AN5: 0 | AO5: 2 | AP5: =VLOOKUP(D5, METADATALOOKUP!$A:$AI, 7, FALSE) -> 51 | AQ5: =VLOOKUP(D5, METADATALOOKUP!$A:$AI, 8, FALSE) -> Male | AR5: =VLOOKUP(D5, METADATALOOKUP!$A:$AI, 9, FALSE) -> White | AS5: =VLOOKUP(D5, METADATALOOKUP!$A:$AI, 11, FALSE) -> No | AT5: =VLOOKUP(D5, METADATALOOKUP!$A:$AI, 10, FALSE) -> Non-Hispanic | AU5: =VLOOKUP(D5, METADATALOOKUP!$A:$AI, 12, FALSE) -> No | AV5: =VLOOKUP(D5, METADATALOOKUP!$A:$AI, 14, FALSE) -> T4aN2cM0 | AW5: =VLOOKUP(D5, METADATALOOKUP!$A:$AI, 6, FALSE) -> High | AX5: =VLOOKUP(D5, METADATALOOKUP!$A:$AI, 19, FALSE) -> Unknown | AY5: =LOOKUP(D5, SURVLOOKUP!$A:$A, SURVLOOKUP!$P:$P) -> 1 | AZ5: 1 | BA5: =TEXT(VLOOKUP(D5, METADATALOOKUP!$A:$AI, 34, FALSE), "@") -> 10-20% | BB5: =IF(AZ5=0, "Non-Responder", "Responder") -> Responder | BC5: 0.16 | BE5: 24 | BF5: 6.25 | BG5: 43.75 | BH5: 21.6 | BI5: 1.157407 | BJ5: UDI0277 | BK5: TATACATC | BL5: AATCTGAA
A6: Pilot2_7 | B6: =VLOOKUP(A6, IDSLOOKUP!C:E, 2, FALSE) -> Day 0 | C6: =VLOOKUP(D6, METADATALOOKUP!$A:$AI, 13, FALSE) -> Oral Cavity | D6: =VLOOKUP(A6, IDSLOOKUP!C:E, 3, FALSE) -> HN01-49 | E6: =VLOOKUP(A6,CFDNALOOKUP!AG:AI,2,FALSE) -> 44090 | F6: =VLOOKUP(A6,CFDNALOOKUP!AG:AI,3,FALSE) -> 44180 | G6: =VLOOKUP(D6, SURVLOOKUP!$A:$Q, 2, FALSE) -> 43656 | H6: =VLOOKUP(D6, SURVLOOKUP!$A:$Q, 3, FALSE) -> 43977 | I6: =VLOOKUP(D6, SURVLOOKUP!$A:$Q, 4, FALSE) -> 43994 | J6: =VLOOKUP(D6, SURVLOOKUP!$A:$Q, 5, FALSE) -> 44012 | K6: =VLOOKUP(D6, SURVLOOKUP!$A:$Q, 6, FALSE) -> NA | L6: =VLOOKUP(D6, SURVLOOKUP!$A:$Q, 7, FALSE) -> NA | M6: =VLOOKUP(D6, SURVLOOKUP!$A:$Q, 8, FALSE) -> 44061 | N6: =VLOOKUP(D6, SURVLOOKUP!$A:$Q, 9, FALSE) -> 44105 | O6: =VLOOKUP(D6, SURVLOOKUP!$A:$Q, 10, FALSE) -> NA | P6: =VLOOKUP(D6, OLDSURVLOOKUP!$A:$AA, 19, FALSE) -> 44159 | Q6: =VLOOKUP(D6, SURVLOOKUP!$A:$Q, 11, FALSE) -> 44159 | R6: =VLOOKUP(D6, OLDSURVLOOKUP!$A:$AA, 20, FALSE) -> 44106 | S6: =VLOOKUP(D6, SURVLOOKUP!$A:$Q, 12, FALSE) -> 44106 | T6: =VLOOKUP(D6, OLDSURVLOOKUP!$A:$AA, 21, FALSE) -> 44160 | U6: =VLOOKUP(D6, SURVLOOKUP!$A:$Q, 13, FALSE) -> 44160 | V6: =_xlfn.XLOOKUP(D6, OLDSURVLOOKUP!$A:$A, OLDSURVLOOKUP!V:V) -> 1 | W6: =VLOOKUP(D6, SURVLOOKUP!$A:$Q, 14, FALSE) -> 1 | X6: =_xlfn.XLOOKUP(D6, OLDSURVLOOKUP!$A:$A, OLDSURVLOOKUP!X:X) -> 1 | Y6: =VLOOKUP(D6, SURVLOOKUP!$A:$Q, 15, FALSE) -> 1 | Z6: =IF(V6=0, DATEDIF(I6,P6,"M")+DATEDIF(I6,P6,"MD")/DAY(EOMONTH(I6,0)), DATEDIF(I6,R6,"M")+DATEDIF(I6,R6,"MD")/DAY(EOMONTH(I6,0))) -> 3.6666667 | AA6: =IF(W6=0, DATEDIF(I6,Q6,"M")+DATEDIF(I6,Q6,"MD")/DAY(EOMONTH(I6,0)), DATEDIF(I6,S6,"M")+DATEDIF(I6,S6,"MD")/DAY(EOMONTH(I6,0))) -> 3.6666667 | AB6: =IF(X6=0, DATEDIF(I6,P6,"M")+DATEDIF(I6,P6,"MD")/DAY(EOMONTH(I6,0)), DATEDIF(I6,T6,"M")+DATEDIF(I6,T6,"MD")/DAY(EOMONTH(I6,0))) -> 5.4333333 | AC6: =IF(Y6=0, DATEDIF(I6,Q6,"M")+DATEDIF(I6,Q6,"MD")/DAY(EOMONTH(I6,0)), DATEDIF(I6,U6,"M")+DATEDIF(I6,U6,"MD")/DAY(EOMONTH(I6,0))) -> 5.4333333 | AD6: =IF(V6=0, DATEDIF(J6,P6,"M")+DATEDIF(J6,P6,"MD")/DAY(EOMONTH(J6,0)), DATEDIF(J6,R6,"M")+DATEDIF(J6,R6,"MD")/DAY(EOMONTH(J6,0))) -> 3.0666667 | AE6: =IF(W6=0, DATEDIF(J6,Q6,"M")+DATEDIF(J6,Q6,"MD")/DAY(EOMONTH(J6,0)), DATEDIF(J6,S6,"M")+DATEDIF(J6,S6,"MD")/DAY(EOMONTH(J6,0))) -> 3.0666667 | AF6: =IF(X6=0, DATEDIF(J6,P6,"M")+DATEDIF(J6,P6,"MD")/DAY(EOMONTH(J6,0)), DATEDIF(J6,T6,"M")+DATEDIF(J6,T6,"MD")/DAY(EOMONTH(J6,0))) -> 4.8666667 | AG6: =IF(Y6=0, DATEDIF(J6,Q6,"M")+DATEDIF(J6,Q6,"MD")/DAY(EOMONTH(J6,0)), DATEDIF(J6,U6,"M")+DATEDIF(J6,U6,"MD")/DAY(EOMONTH(J6,0))) -> 4.8666667 | AH6: =IF(V6=0, DATEDIF(M6,P6,"M")+DATEDIF(M6,P6,"MD")/DAY(EOMONTH(M6,0)), DATEDIF(M6,R6,"M")+DATEDIF(M6,R6,"MD")/DAY(EOMONTH(M6,0))) -> 1.4516129 | AI6: =IF(W6=0, DATEDIF(M6,Q6,"M")+DATEDIF(M6,Q6,"MD")/DAY(EOMONTH(M6,0)), DATEDIF(M6,S6,"M")+DATEDIF(M6,S6,"MD")/DAY(EOMONTH(M6,0))) -> 1.4516129 | AJ6: =IF(X6=0, DATEDIF(M6,P6,"M")+DATEDIF(M6,P6,"MD")/DAY(EOMONTH(M6,0)), DATEDIF(M6,T6,"M")+DATEDIF(M6,T6,"MD")/DAY(EOMONTH(M6,0))) -> 3.2258065 | AK6: =IF(Y6=0, DATEDIF(M6,Q6,"M")+DATEDIF(M6,Q6,"MD")/DAY(EOMONTH(M6,0)), DATEDIF(M6,U6,"M")+DATEDIF(M6,U6,"MD")/DAY(EOMONTH(M6,0))) -> 3.2258065 | AL6: =IF(MID(A6,FIND("_",A6)-1,1)="2", 2, 1) -> 2 | AM6: =IFERROR( CHOOSE( VALUE(MID(D6, FIND("-", D6) - 1, 1)), "University of Cincinnati", "Ohio State University", "Medical University of South Carolina", "University of Michigan", "University of Louisville", "MD Anderson" ), "Unknown" ) -> University of Cincinnati | AN6: 0 | AO6: 2 | AP6: =VLOOKUP(D6, METADATALOOKUP!$A:$AI, 7, FALSE) -> 51 | AQ6: =VLOOKUP(D6, METADATALOOKUP!$A:$AI, 8, FALSE) -> Male | AR6: =VLOOKUP(D6, METADATALOOKUP!$A:$AI, 9, FALSE) -> White | AS6: =VLOOKUP(D6, METADATALOOKUP!$A:$AI, 11, FALSE) -> No | AT6: =VLOOKUP(D6, METADATALOOKUP!$A:$AI, 10, FALSE) -> Non-Hispanic | AU6: =VLOOKUP(D6, METADATALOOKUP!$A:$AI, 12, FALSE) -> No | AV6: =VLOOKUP(D6, METADATALOOKUP!$A:$AI, 14, FALSE) -> T4aN2cM0 | AW6: =VLOOKUP(D6, METADATALOOKUP!$A:$AI, 6, FALSE) -> High | AX6: =VLOOKUP(D6, METADATALOOKUP!$A:$AI, 19, FALSE) -> Unknown | AY6: =LOOKUP(D6, SURVLOOKUP!$A:$A, SURVLOOKUP!$P:$P) -> 1 | AZ6: 1 | BA6: =TEXT(VLOOKUP(D6, METADATALOOKUP!$A:$AI, 34, FALSE), "@") -> 10-20% | BB6: =IF(AZ6=0, "Non-Responder", "Responder") -> Responder | BC6: 0.316 | BE6: 24 | BF6: 3.164557 | BG6: 46.83544 | BH6: 20.2 | BI6: 1.237624 | BJ6: UDI0207 | BK6: ACATGATA | BL6: CGTAGATA
A7: Pilot2_8 | B7: =VLOOKUP(A7, IDSLOOKUP!C:E, 2, FALSE) -> Adj Wk 1 | C7: =VLOOKUP(D7, METADATALOOKUP!$A:$AI, 13, FALSE) -> Oral Cavity | D7: =VLOOKUP(A7, IDSLOOKUP!C:E, 3, FALSE) -> HN01-49 | E7: =VLOOKUP(A7,CFDNALOOKUP!AG:AI,2,FALSE) -> 44090 | F7: =VLOOKUP(A7,CFDNALOOKUP!AG:AI,3,FALSE) -> 44180 | G7: =VLOOKUP(D7, SURVLOOKUP!$A:$Q, 2, FALSE) -> 43656 | H7: =VLOOKUP(D7, SURVLOOKUP!$A:$Q, 3, FALSE) -> 43977 | I7: =VLOOKUP(D7, SURVLOOKUP!$A:$Q, 4, FALSE) -> 43994 | J7: =VLOOKUP(D7, SURVLOOKUP!$A:$Q, 5, FALSE) -> 44012 | K7: =VLOOKUP(D7, SURVLOOKUP!$A:$Q, 6, FALSE) -> NA | L7: =VLOOKUP(D7, SURVLOOKUP!$A:$Q, 7, FALSE) -> NA | M7: =VLOOKUP(D7, SURVLOOKUP!$A:$Q, 8, FALSE) -> 44061 | N7: =VLOOKUP(D7, SURVLOOKUP!$A:$Q, 9, FALSE) -> 44105 | O7: =VLOOKUP(D7, SURVLOOKUP!$A:$Q, 10, FALSE) -> NA | P7: =VLOOKUP(D7, OLDSURVLOOKUP!$A:$AA, 19, FALSE) -> 44159 | Q7: =VLOOKUP(D7, SURVLOOKUP!$A:$Q, 11, FALSE) -> 44159 | R7: =VLOOKUP(D7, OLDSURVLOOKUP!$A:$AA, 20, FALSE) -> 44106 | S7: =VLOOKUP(D7, SURVLOOKUP!$A:$Q, 12, FALSE) -> 44106 | T7: =VLOOKUP(D7, OLDSURVLOOKUP!$A:$AA, 21, FALSE) -> 44160 | U7: =VLOOKUP(D7, SURVLOOKUP!$A:$Q, 13, FALSE) -> 44160 | V7: =_xlfn.XLOOKUP(D7, OLDSURVLOOKUP!$A:$A, OLDSURVLOOKUP!V:V) -> 1 | W7: =VLOOKUP(D7, SURVLOOKUP!$A:$Q, 14, FALSE) -> 1 | X7: =_xlfn.XLOOKUP(D7, OLDSURVLOOKUP!$A:$A, OLDSURVLOOKUP!X:X) -> 1 | Y7: =VLOOKUP(D7, SURVLOOKUP!$A:$Q, 15, FALSE) -> 1 | Z7: =IF(V7=0, DATEDIF(I7,P7,"M")+DATEDIF(I7,P7,"MD")/DAY(EOMONTH(I7,0)), DATEDIF(I7,R7,"M")+DATEDIF(I7,R7,"MD")/DAY(EOMONTH(I7,0))) -> 3.6666667 | AA7: =IF(W7=0, DATEDIF(I7,Q7,"M")+DATEDIF(I7,Q7,"MD")/DAY(EOMONTH(I7,0)), DATEDIF(I7,S7,"M")+DATEDIF(I7,S7,"MD")/DAY(EOMONTH(I7,0))) -> 3.6666667 | AB7: =IF(X7=0, DATEDIF(I7,P7,"M")+DATEDIF(I7,P7,"MD")/DAY(EOMONTH(I7,0)), DATEDIF(I7,T7,"M")+DATEDIF(I7,T7,"MD")/DAY(EOMONTH(I7,0))) -> 5.4333333 | AC7: =IF(Y7=0, DATEDIF(I7,Q7,"M")+DATEDIF(I7,Q7,"MD")/DAY(EOMONTH(I7,0)), DATEDIF(I7,U7,"M")+DATEDIF(I7,U7,"MD")/DAY(EOMONTH(I7,0))) -> 5.4333333 | AD7: =IF(V7=0, DATEDIF(J7,P7,"M")+DATEDIF(J7,P7,"MD")/DAY(EOMONTH(J7,0)), DATEDIF(J7,R7,"M")+DATEDIF(J7,R7,"MD")/DAY(EOMONTH(J7,0))) -> 3.0666667 | AE7: =IF(W7=0, DATEDIF(J7,Q7,"M")+DATEDIF(J7,Q7,"MD")/DAY(EOMONTH(J7,0)), DATEDIF(J7,S7,"M")+DATEDIF(J7,S7,"MD")/DAY(EOMONTH(J7,0))) -> 3.0666667 | AF7: =IF(X7=0, DATEDIF(J7,P7,"M")+DATEDIF(J7,P7,"MD")/DAY(EOMONTH(J7,0)), DATEDIF(J7,T7,"M")+DATEDIF(J7,T7,"MD")/DAY(EOMONTH(J7,0))) -> 4.8666667 | AG7: =IF(Y7=0, DATEDIF(J7,Q7,"M")+DATEDIF(J7,Q7,"MD")/DAY(EOMONTH(J7,0)), DATEDIF(J7,U7,"M")+DATEDIF(J7,U7,"MD")/DAY(EOMONTH(J7,0))) -> 4.8666667 | AH7: =IF(V7=0, DATEDIF(M7,P7,"M")+DATEDIF(M7,P7,"MD")/DAY(EOMONTH(M7,0)), DATEDIF(M7,R7,"M")+DATEDIF(M7,R7,"MD")/DAY(EOMONTH(M7,0))) -> 1.4516129 | AI7: =IF(W7=0, DATEDIF(M7,Q7,"M")+DATEDIF(M7,Q7,"MD")/DAY(EOMONTH(M7,0)), DATEDIF(M7,S7,"M")+DATEDIF(M7,S7,"MD")/DAY(EOMONTH(M7,0))) -> 1.4516129 | AJ7: =IF(X7=0, DATEDIF(M7,P7,"M")+DATEDIF(M7,P7,"MD")/DAY(EOMONTH(M7,0)), DATEDIF(M7,T7,"M")+DATEDIF(M7,T7,"MD")/DAY(EOMONTH(M7,0))) -> 3.2258065 | AK7: =IF(Y7=0, DATEDIF(M7,Q7,"M")+DATEDIF(M7,Q7,"MD")/DAY(EOMONTH(M7,0)), DATEDIF(M7,U7,"M")+DATEDIF(M7,U7,"MD")/DAY(EOMONTH(M7,0))) -> 3.2258065 | AL7: =IF(MID(A7,FIND("_",A7)-1,1)="2", 2, 1) -> 2 | AM7: =IFERROR( CHOOSE( VALUE(MID(D7, FIND("-", D7) - 1, 1)), "University of Cincinnati", "Ohio State University", "Medical University of South Carolina", "University of Michigan", "University of Louisville", "MD Anderson" ), "Unknown" ) -> University of Cincinnati | AN7: 0 | AO7: 2 | AP7: =VLOOKUP(D7, METADATALOOKUP!$A:$AI, 7, FALSE) -> 51 | AQ7: =VLOOKUP(D7, METADATALOOKUP!$A:$AI, 8, FALSE) -> Male | AR7: =VLOOKUP(D7, METADATALOOKUP!$A:$AI, 9, FALSE) -> White | AS7: =VLOOKUP(D7, METADATALOOKUP!$A:$AI, 11, FALSE) -> No | AT7: =VLOOKUP(D7, METADATALOOKUP!$A:$AI, 10, FALSE) -> Non-Hispanic | AU7: =VLOOKUP(D7, METADATALOOKUP!$A:$AI, 12, FALSE) -> No | AV7: =VLOOKUP(D7, METADATALOOKUP!$A:$AI, 14, FALSE) -> T4aN2cM0 | AW7: =VLOOKUP(D7, METADATALOOKUP!$A:$AI, 6, FALSE) -> High | AX7: =VLOOKUP(D7, METADATALOOKUP!$A:$AI, 19, FALSE) -> Unknown | AY7: =LOOKUP(D7, SURVLOOKUP!$A:$A, SURVLOOKUP!$P:$P) -> 1 | AZ7: 1 | BA7: =TEXT(VLOOKUP(D7, METADATALOOKUP!$A:$AI, 34, FALSE), "@") -> 10-20% | BB7: =IF(AZ7=0, "Non-Responder", "Responder") -> Responder | BC7: 0.188 | BE7: 24 | BF7: 5.319149 | BG7: 44.68085 | BH7: 16.8 | BI7: 1.488095 | BJ7: UDI0230 | BK7: GATGGAGT | BL7: TTCCAGGC
A8: Pilot2_9 | B8: =VLOOKUP(A8, IDSLOOKUP!C:E, 2, FALSE) -> Screen | C8: =VLOOKUP(D8, METADATALOOKUP!$A:$AI, 13, FALSE) -> Oral Cavity | D8: =VLOOKUP(A8, IDSLOOKUP!C:E, 3, FALSE) -> HN01-50 | E8: =VLOOKUP(A8,CFDNALOOKUP!AG:AI,2,FALSE) -> 44090 | F8: =VLOOKUP(A8,CFDNALOOKUP!AG:AI,3,FALSE) -> 44179 | G8: =VLOOKUP(D8, SURVLOOKUP!$A:$Q, 2, FALSE) -> 43972 | H8: =VLOOKUP(D8, SURVLOOKUP!$A:$Q, 3, FALSE) -> 43990 | I8: =VLOOKUP(D8, SURVLOOKUP!$A:$Q, 4, FALSE) -> 43994 | J8: =VLOOKUP(D8, SURVLOOKUP!$A:$Q, 5, FALSE) -> 44001 | K8: =VLOOKUP(D8, SURVLOOKUP!$A:$Q, 6, FALSE) -> 44039 | L8: =VLOOKUP(D8, SURVLOOKUP!$A:$Q, 7, FALSE) -> 44078 | M8: =VLOOKUP(D8, SURVLOOKUP!$A:$Q, 8, FALSE) -> 44033 | N8: =VLOOKUP(D8, SURVLOOKUP!$A:$Q, 9, FALSE) -> 44159 | O8: =VLOOKUP(D8, SURVLOOKUP!$A:$Q, 10, FALSE) -> NA | P8: =VLOOKUP(D8, OLDSURVLOOKUP!$A:$AA, 19, FALSE) -> 44341 | Q8: =VLOOKUP(D8, SURVLOOKUP!$A:$Q, 11, FALSE) -> 45678 | V8: =_xlfn.XLOOKUP(D8, OLDSURVLOOKUP!$A:$A, OLDSURVLOOKUP!V:V) -> 0 | W8: =VLOOKUP(D8, SURVLOOKUP!$A:$Q, 14, FALSE) -> 0 | X8: =_xlfn.XLOOKUP(D8, OLDSURVLOOKUP!$A:$A, OLDSURVLOOKUP!X:X) -> 0 | Y8: =VLOOKUP(D8, SURVLOOKUP!$A:$Q, 15, FALSE) -> 0 | Z8: =IF(V8=0, DATEDIF(I8,P8,"M")+DATEDIF(I8,P8,"MD")/DAY(EOMONTH(I8,0)), DATEDIF(I8,R8,"M")+DATEDIF(I8,R8,"MD")/DAY(EOMONTH(I8,0))) -> 11.433333 | AA8: =IF(W8=0, DATEDIF(I8,Q8,"M")+DATEDIF(I8,Q8,"MD")/DAY(EOMONTH(I8,0)), DATEDIF(I8,S8,"M")+DATEDIF(I8,S8,"MD")/DAY(EOMONTH(I8,0))) -> 55.3 | AB8: =IF(X8=0, DATEDIF(I8,P8,"M")+DATEDIF(I8,P8,"MD")/DAY(EOMONTH(I8,0)), DATEDIF(I8,T8,"M")+DATEDIF(I8,T8,"MD")/DAY(EOMONTH(I8,0))) -> 11.433333 | AC8: =IF(Y8=0, DATEDIF(I8,Q8,"M")+DATEDIF(I8,Q8,"MD")/DAY(EOMONTH(I8,0)), DATEDIF(I8,U8,"M")+DATEDIF(I8,U8,"MD")/DAY(EOMONTH(I8,0))) -> 55.3 | AD8: =IF(V8=0, DATEDIF(J8,P8,"M")+DATEDIF(J8,P8,"MD")/DAY(EOMONTH(J8,0)), DATEDIF(J8,R8,"M")+DATEDIF(J8,R8,"MD")/DAY(EOMONTH(J8,0))) -> 11.2 | AE8: =IF(W8=0, DATEDIF(J8,Q8,"M")+DATEDIF(J8,Q8,"MD")/DAY(EOMONTH(J8,0)), DATEDIF(J8,S8,"M")+DATEDIF(J8,S8,"MD")/DAY(EOMONTH(J8,0))) -> 55.066667 | AF8: =IF(X8=0, DATEDIF(J8,P8,"M")+DATEDIF(J8,P8,"MD")/DAY(EOMONTH(J8,0)), DATEDIF(J8,T8,"M")+DATEDIF(J8,T8,"MD")/DAY(EOMONTH(J8,0))) -> 11.2 | AG8: =IF(Y8=0, DATEDIF(J8,Q8,"M")+DATEDIF(J8,Q8,"MD")/DAY(EOMONTH(J8,0)), DATEDIF(J8,U8,"M")+DATEDIF(J8,U8,"MD")/DAY(EOMONTH(J8,0))) -> 55.066667 | AH8: =IF(V8=0, DATEDIF(M8,P8,"M")+DATEDIF(M8,P8,"MD")/DAY(EOMONTH(M8,0)), DATEDIF(M8,R8,"M")+DATEDIF(M8,R8,"MD")/DAY(EOMONTH(M8,0))) -> 10.129032 | AI8: =IF(W8=0, DATEDIF(M8,Q8,"M")+DATEDIF(M8,Q8,"MD")/DAY(EOMONTH(M8,0)), DATEDIF(M8,S8,"M")+DATEDIF(M8,S8,"MD")/DAY(EOMONTH(M8,0))) -> 54 | AJ8: =IF(X8=0, DATEDIF(M8,P8,"M")+DATEDIF(M8,P8,"MD")/DAY(EOMONTH(M8,0)), DATEDIF(M8,T8,"M")+DATEDIF(M8,T8,"MD")/DAY(EOMONTH(M8,0))) -> 10.129032 | AK8: =IF(Y8=0, DATEDIF(M8,Q8,"M")+DATEDIF(M8,Q8,"MD")/DAY(EOMONTH(M8,0)), DATEDIF(M8,U8,"M")+DATEDIF(M8,U8,"MD")/DAY(EOMONTH(M8,0))) -> 54 | AL8: =IF(MID(A8,FIND("_",A8)-1,1)="2", 2, 1) -> 2 | AM8: =IFERROR( CHOOSE( VALUE(MID(D8, FIND("-", D8) - 1, 1)), "University of Cincinnati", "Ohio State University", "Medical University of South Carolina", "University of Michigan", "University of Louisville", "MD Anderson" ), "Unknown" ) -> University of Cincinnati | AN8: 0 | AO8: 3 | AP8: =VLOOKUP(D8, METADATALOOKUP!$A:$AI, 7, FALSE) -> 71 | AQ8: =VLOOKUP(D8, METADATALOOKUP!$A:$AI, 8, FALSE) -> Female | AR8: =VLOOKUP(D8, METADATALOOKUP!$A:$AI, 9, FALSE) -> White | AS8: =VLOOKUP(D8, METADATALOOKUP!$A:$AI, 11, FALSE) -> Yes | AT8: =VLOOKUP(D8, METADATALOOKUP!$A:$AI, 10, FALSE) -> Non-Hispanic | AU8: =VLOOKUP(D8, METADATALOOKUP!$A:$AI, 12, FALSE) -> No | AV8: =VLOOKUP(D8, METADATALOOKUP!$A:$AI, 14, FALSE) -> T4aN2bM0 | AW8: =VLOOKUP(D8, METADATALOOKUP!$A:$AI, 6, FALSE) -> High | AX8: =VLOOKUP(D8, METADATALOOKUP!$A:$AI, 19, FALSE) -> Unknown | AY8: =LOOKUP(D8, SURVLOOKUP!$A:$A, SURVLOOKUP!$P:$P) -> 1 | AZ8: 1 | BA8: =TEXT(VLOOKUP(D8, METADATALOOKUP!$A:$AI, 34, FALSE), "@") -> 10-20% | BB8: =IF(AZ8=0, "Non-Responder", "Responder") -> Responder | BC8: 0.16 | BE8: 24 | BF8: 6.25 | BG8: 43.75 | BH8: 19.8 | BI8: 1.262626 | BJ8: UDI0241 | BK8: ATATATAC | BL8: AATGCTTG
A9: Pilot2_10 | B9: =VLOOKUP(A9, IDSLOOKUP!C:E, 2, FALSE) -> Day 0 | C9: =VLOOKUP(D9, METADATALOOKUP!$A:$AI, 13, FALSE) -> Oral Cavity | D9: =VLOOKUP(A9, IDSLOOKUP!C:E, 3, FALSE) -> HN01-50 | E9: =VLOOKUP(A9,CFDNALOOKUP!AG:AI,2,FALSE) -> 44090 | F9: =VLOOKUP(A9,CFDNALOOKUP!AG:AI,3,FALSE) -> 44179 | G9: =VLOOKUP(D9, SURVLOOKUP!$A:$Q, 2, FALSE) -> 43972 | H9: =VLOOKUP(D9, SURVLOOKUP!$A:$Q, 3, FALSE) -> 43990 | I9: =VLOOKUP(D9, SURVLOOKUP!$A:$Q, 4, FALSE) -> 43994 | J9: =VLOOKUP(D9, SURVLOOKUP!$A:$Q, 5, FALSE) -> 44001 | K9: =VLOOKUP(D9, SURVLOOKUP!$A:$Q, 6, FALSE) -> 44039 | L9: =VLOOKUP(D9, SURVLOOKUP!$A:$Q, 7, FALSE) -> 44078 | M9: =VLOOKUP(D9, SURVLOOKUP!$A:$Q, 8, FALSE) -> 44033 | N9: =VLOOKUP(D9, SURVLOOKUP!$A:$Q, 9, FALSE) -> 44159 | O9: =VLOOKUP(D9, SURVLOOKUP!$A:$Q, 10, FALSE) -> NA | P9: =VLOOKUP(D9, OLDSURVLOOKUP!$A:$AA, 19, FALSE) -> 44341 | Q9: =VLOOKUP(D9, SURVLOOKUP!$A:$Q, 11, FALSE) -> 45678 | V9: =_xlfn.XLOOKUP(D9, OLDSURVLOOKUP!$A:$A, OLDSURVLOOKUP!V:V) -> 0 | W9: =VLOOKUP(D9, SURVLOOKUP!$A:$Q, 14, FALSE) -> 0 | X9: =_xlfn.XLOOKUP(D9, OLDSURVLOOKUP!$A:$A, OLDSURVLOOKUP!X:X) -> 0 | Y9: =VLOOKUP(D9, SURVLOOKUP!$A:$Q, 15, FALSE) -> 0 | Z9: =IF(V9=0, DATEDIF(I9,P9,"M")+DATEDIF(I9,P9,"MD")/DAY(EOMONTH(I9,0)), DATEDIF(I9,R9,"M")+DATEDIF(I9,R9,"MD")/DAY(EOMONTH(I9,0))) -> 11.433333 | AA9: =IF(W9=0, DATEDIF(I9,Q9,"M")+DATEDIF(I9,Q9,"MD")/DAY(EOMONTH(I9,0)), DATEDIF(I9,S9,"M")+DATEDIF(I9,S9,"MD")/DAY(EOMONTH(I9,0))) -> 55.3 | AB9: =IF(X9=0, DATEDIF(I9,P9,"M")+DATEDIF(I9,P9,"MD")/DAY(EOMONTH(I9,0)), DATEDIF(I9,T9,"M")+DATEDIF(I9,T9,"MD")/DAY(EOMONTH(I9,0))) -> 11.433333 | AC9: =IF(Y9=0, DATEDIF(I9,Q9,"M")+DATEDIF(I9,Q9,"MD")/DAY(EOMONTH(I9,0)), DATEDIF(I9,U9,"M")+DATEDIF(I9,U9,"MD")/DAY(EOMONTH(I9,0))) -> 55.3 | AD9: =IF(V9=0, DATEDIF(J9,P9,"M")+DATEDIF(J9,P9,"MD")/DAY(EOMONTH(J9,0)), DATEDIF(J9,R9,"M")+DATEDIF(J9,R9,"MD")/DAY(EOMONTH(J9,0))) -> 11.2 | AE9: =IF(W9=0, DATEDIF(J9,Q9,"M")+DATEDIF(J9,Q9,"MD")/DAY(EOMONTH(J9,0)), DATEDIF(J9,S9,"M")+DATEDIF(J9,S9,"MD")/DAY(EOMONTH(J9,0))) -> 55.066667 | AF9: =IF(X9=0, DATEDIF(J9,P9,"M")+DATEDIF(J9,P9,"MD")/DAY(EOMONTH(J9,0)), DATEDIF(J9,T9,"M")+DATEDIF(J9,T9,"MD")/DAY(EOMONTH(J9,0))) -> 11.2 | AG9: =IF(Y9=0, DATEDIF(J9,Q9,"M")+DATEDIF(J9,Q9,"MD")/DAY(EOMONTH(J9,0)), DATEDIF(J9,U9,"M")+DATEDIF(J9,U9,"MD")/DAY(EOMONTH(J9,0))) -> 55.066667 | AH9: =IF(V9=0, DATEDIF(M9,P9,"M")+DATEDIF(M9,P9,"MD")/DAY(EOMONTH(M9,0)), DATEDIF(M9,R9,"M")+DATEDIF(M9,R9,"MD")/DAY(EOMONTH(M9,0))) -> 10.129032 | AI9: =IF(W9=0, DATEDIF(M9,Q9,"M")+DATEDIF(M9,Q9,"MD")/DAY(EOMONTH(M9,0)), DATEDIF(M9,S9,"M")+DATEDIF(M9,S9,"MD")/DAY(EOMONTH(M9,0))) -> 54 | AJ9: =IF(X9=0, DATEDIF(M9,P9,"M")+DATEDIF(M9,P9,"MD")/DAY(EOMONTH(M9,0)), DATEDIF(M9,T9,"M")+DATEDIF(M9,T9,"MD")/DAY(EOMONTH(M9,0))) -> 10.129032 | AK9: =IF(Y9=0, DATEDIF(M9,Q9,"M")+DATEDIF(M9,Q9,"MD")/DAY(EOMONTH(M9,0)), DATEDIF(M9,U9,"M")+DATEDIF(M9,U9,"MD")/DAY(EOMONTH(M9,0))) -> 54 | AL9: =IF(MID(A9,FIND("_",A9)-1,1)="2", 2, 1) -> 2 | AM9: =IFERROR( CHOOSE( VALUE(MID(D9, FIND("-", D9) - 1, 1)), "University of Cincinnati", "Ohio State University", "Medical University of South Carolina", "University of Michigan", "University of Louisville", "MD Anderson" ), "Unknown" ) -> University of Cincinnati | AN9: 0 | AO9: 3 | AP9: =VLOOKUP(D9, METADATALOOKUP!$A:$AI, 7, FALSE) -> 71 | AQ9: =VLOOKUP(D9, METADATALOOKUP!$A:$AI, 8, FALSE) -> Female | AR9: =VLOOKUP(D9, METADATALOOKUP!$A:$AI, 9, FALSE) -> White | AS9: =VLOOKUP(D9, METADATALOOKUP!$A:$AI, 11, FALSE) -> Yes | AT9: =VLOOKUP(D9, METADATALOOKUP!$A:$AI, 10, FALSE) -> Non-Hispanic | AU9: =VLOOKUP(D9, METADATALOOKUP!$A:$AI, 12, FALSE) -> No | AV9: =VLOOKUP(D9, METADATALOOKUP!$A:$AI, 14, FALSE) -> T4aN2bM0 | AW9: =VLOOKUP(D9, METADATALOOKUP!$A:$AI, 6, FALSE) -> High | AX9: =VLOOKUP(D9, METADATALOOKUP!$A:$AI, 19, FALSE) -> Unknown | AY9: =LOOKUP(D9, SURVLOOKUP!$A:$A, SURVLOOKUP!$P:$P) -> 1 | AZ9: 1 | BA9: =TEXT(VLOOKUP(D9, METADATALOOKUP!$A:$AI, 34, FALSE), "@") -> 10-20% | BB9: =IF(AZ9=0, "Non-Responder", "Responder") -> Responder | BC9: 0.2 | BE9: 24 | BF9: 5 | BG9: 45 | BH9: 19.8 | BI9: 1.262626 | BJ9: UDI0266 | BK9: ATCGTGGA | BL9: GGCCGTTG
A10: Pilot2_11 | B10: =VLOOKUP(A10, IDSLOOKUP!C:E, 2, FALSE) -> Adj Wk 1 | C10: =VLOOKUP(D10, METADATALOOKUP!$A:$AI, 13, FALSE) -> Oral Cavity | D10: =VLOOKUP(A10, IDSLOOKUP!C:E, 3, FALSE) -> HN01-50 | E10: =VLOOKUP(A10,CFDNALOOKUP!AG:AI,2,FALSE) -> 44090 | F10: =VLOOKUP(A10,CFDNALOOKUP!AG:AI,3,FALSE) -> 44179 | G10: =VLOOKUP(D10, SURVLOOKUP!$A:$Q, 2, FALSE) -> 43972 | H10: =VLOOKUP(D10, SURVLOOKUP!$A:$Q, 3, FALSE) -> 43990 | I10: =VLOOKUP(D10, SURVLOOKUP!$A:$Q, 4, FALSE) -> 43994 | J10: =VLOOKUP(D10, SURVLOOKUP!$A:$Q, 5, FALSE) -> 44001 | K10: =VLOOKUP(D10, SURVLOOKUP!$A:$Q, 6, FALSE) -> 44039 | L10: =VLOOKUP(D10, SURVLOOKUP!$A:$Q, 7, FALSE) -> 44078 | M10: =VLOOKUP(D10, SURVLOOKUP!$A:$Q, 8, FALSE) -> 44033 | N10: =VLOOKUP(D10, SURVLOOKUP!$A:$Q, 9, FALSE) -> 44159 | O10: =VLOOKUP(D10, SURVLOOKUP!$A:$Q, 10, FALSE) -> NA | P10: =VLOOKUP(D10, OLDSURVLOOKUP!$A:$AA, 19, FALSE) -> 44341 | Q10: =VLOOKUP(D10, SURVLOOKUP!$A:$Q, 11, FALSE) -> 45678 | V10: =_xlfn.XLOOKUP(D10, OLDSURVLOOKUP!$A:$A, OLDSURVLOOKUP!V:V) -> 0 | W10: =VLOOKUP(D10, SURVLOOKUP!$A:$Q, 14, FALSE) -> 0 | X10: =_xlfn.XLOOKUP(D10, OLDSURVLOOKUP!$A:$A, OLDSURVLOOKUP!X:X) -> 0 | Y10: =VLOOKUP(D10, SURVLOOKUP!$A:$Q, 15, FALSE) -> 0 | Z10: =IF(V10=0, DATEDIF(I10,P10,"M")+DATEDIF(I10,P10,"MD")/DAY(EOMONTH(I10,0)), DATEDIF(I10,R10,"M")+DATEDIF(I10,R10,"MD")/DAY(EOMONTH(I10,0))) -> 11.433333 | AA10: =IF(W10=0, DATEDIF(I10,Q10,"M")+DATEDIF(I10,Q10,"MD")/DAY(EOMONTH(I10,0)), DATEDIF(I10,S10,"M")+DATEDIF(I10,S10,"MD")/DAY(EOMONTH(I10,0))) -> 55.3 | AB10: =IF(X10=0, DATEDIF(I10,P10,"M")+DATEDIF(I10,P10,"MD")/DAY(EOMONTH(I10,0)), DATEDIF(I10,T10,"M")+DATEDIF(I10,T10,"MD")/DAY(EOMONTH(I10,0))) -> 11.433333 | AC10: =IF(Y10=0, DATEDIF(I10,Q10,"M")+DATEDIF(I10,Q10,"MD")/DAY(EOMONTH(I10,0)), DATEDIF(I10,U10,"M")+DATEDIF(I10,U10,"MD")/DAY(EOMONTH(I10,0))) -> 55.3 | AD10: =IF(V10=0, DATEDIF(J10,P10,"M")+DATEDIF(J10,P10,"MD")/DAY(EOMONTH(J10,0)), DATEDIF(J10,R10,"M")+DATEDIF(J10,R10,"MD")/DAY(EOMONTH(J10,0))) -> 11.2 | AE10: =IF(W10=0, DATEDIF(J10,Q10,"M")+DATEDIF(J10,Q10,"MD")/DAY(EOMONTH(J10,0)), DATEDIF(J10,S10,"M")+DATEDIF(J10,S10,"MD")/DAY(EOMONTH(J10,0))) -> 55.066667 | AF10: =IF(X10=0, DATEDIF(J10,P10,"M")+DATEDIF(J10,P10,"MD")/DAY(EOMONTH(J10,0)), DATEDIF(J10,T10,"M")+DATEDIF(J10,T10,"MD")/DAY(EOMONTH(J10,0))) -> 11.2 | AG10: =IF(Y10=0, DATEDIF(J10,Q10,"M")+DATEDIF(J10,Q10,"MD")/DAY(EOMONTH(J10,0)), DATEDIF(J10,U10,"M")+DATEDIF(J10,U10,"MD")/DAY(EOMONTH(J10,0))) -> 55.066667 | AH10: =IF(V10=0, DATEDIF(M10,P10,"M")+DATEDIF(M10,P10,"MD")/DAY(EOMONTH(M10,0)), DATEDIF(M10,R10,"M")+DATEDIF(M10,R10,"MD")/DAY(EOMONTH(M10,0))) -> 10.129032 | AI10: =IF(W10=0, DATEDIF(M10,Q10,"M")+DATEDIF(M10,Q10,"MD")/DAY(EOMONTH(M10,0)), DATEDIF(M10,S10,"M")+DATEDIF(M10,S10,"MD")/DAY(EOMONTH(M10,0))) -> 54 | AJ10: =IF(X10=0, DATEDIF(M10,P10,"M")+DATEDIF(M10,P10,"MD")/DAY(EOMONTH(M10,0)), DATEDIF(M10,T10,"M")+DATEDIF(M10,T10,"MD")/DAY(EOMONTH(M10,0))) -> 10.129032 | AK10: =IF(Y10=0, DATEDIF(M10,Q10,"M")+DATEDIF(M10,Q10,"MD")/DAY(EOMONTH(M10,0)), DATEDIF(M10,U10,"M")+DATEDIF(M10,U10,"MD")/DAY(EOMONTH(M10,0))) -> 54 | AL10: =IF(MID(A10,FIND("_",A10)-1,1)="2", 2, 1) -> 2 | AM10: =IFERROR( CHOOSE( VALUE(MID(D10, FIND("-", D10) - 1, 1)), "University of Cincinnati", "Ohio State University", "Medical University of South Carolina", "University of Michigan", "University of Louisville", "MD Anderson" ), "Unknown" ) -> University of Cincinnati | AN10: 0 | AO10: 3 | AP10: =VLOOKUP(D10, METADATALOOKUP!$A:$AI, 7, FALSE) -> 71 | AQ10: =VLOOKUP(D10, METADATALOOKUP!$A:$AI, 8, FALSE) -> Female | AR10: =VLOOKUP(D10, METADATALOOKUP!$A:$AI, 9, FALSE) -> White | AS10: =VLOOKUP(D10, METADATALOOKUP!$A:$AI, 11, FALSE) -> Yes | AT10: =VLOOKUP(D10, METADATALOOKUP!$A:$AI, 10, FALSE) -> Non-Hispanic | AU10: =VLOOKUP(D10, METADATALOOKUP!$A:$AI, 12, FALSE) -> No | AV10: =VLOOKUP(D10, METADATALOOKUP!$A:$AI, 14, FALSE) -> T4aN2bM0 | AW10: =VLOOKUP(D10, METADATALOOKUP!$A:$AI, 6, FALSE) -> High | AX10: =VLOOKUP(D10, METADATALOOKUP!$A:$AI, 19, FALSE) -> Unknown | AY10: =LOOKUP(D10, SURVLOOKUP!$A:$A, SURVLOOKUP!$P:$P) -> 1 | AZ10: 1 | BA10: =TEXT(VLOOKUP(D10, METADATALOOKUP!$A:$AI, 34, FALSE), "@") -> 10-20% | BB10: =IF(AZ10=0, "Non-Responder", "Responder") -> Responder | BC10: 0.166 | BE10: 24 | BF10: 6.024096 | BG10: 43.9759 | BH10: 25.4 | BI10: 0.984252 | BJ10: UDI0277 | BK10: TATACATC | BL10: AATCTGAA
A11: Pilot2_12 | B11: =VLOOKUP(A11, IDSLOOKUP!C:E, 2, FALSE) -> Screen | C11: =(_xlfn.XLOOKUP(D11,RAWMETADATALOOKUP_P1!A:A,RAWMETADATALOOKUP_P1!M:M)) -> Larynx | D11: =VLOOKUP(A11, IDSLOOKUP!C:E, 3, FALSE) -> HN01-51 | E11: =VLOOKUP(A11,CFDNALOOKUP!AG:AI,2,FALSE) -> 44090 | F11: =VLOOKUP(A11,CFDNALOOKUP!AG:AI,3,FALSE) -> 44180 | G11: =VLOOKUP(D11, SURVLOOKUP!$A:$Q, 2, FALSE) -> 43974 | H11: =VLOOKUP(D11, SURVLOOKUP!$A:$Q, 3, FALSE) -> 43997 | I11: =VLOOKUP(D11, SURVLOOKUP!$A:$Q, 4, FALSE) -> 44000 | J11: =VLOOKUP(D11, SURVLOOKUP!$A:$Q, 5, FALSE) -> 44008 | K11: =VLOOKUP(D11, SURVLOOKUP!$A:$Q, 6, FALSE) -> NA | L11: =VLOOKUP(D11, SURVLOOKUP!$A:$Q, 7, FALSE) -> NA | M11: =VLOOKUP(D11, SURVLOOKUP!$A:$Q, 8, FALSE) -> NA | N11: =VLOOKUP(D11, SURVLOOKUP!$A:$Q, 9, FALSE) -> NA | O11: =VLOOKUP(D11, SURVLOOKUP!$A:$Q, 10, FALSE) -> NA | P11: =VLOOKUP(D11, OLDSURVLOOKUP!$A:$AA, 19, FALSE) -> 44333 | Q11: =VLOOKUP(D11, SURVLOOKUP!$A:$Q, 11, FALSE) -> 45064 | V11: =_xlfn.XLOOKUP(D11, OLDSURVLOOKUP!$A:$A, OLDSURVLOOKUP!V:V) -> 0 | W11: =VLOOKUP(D11, SURVLOOKUP!$A:$Q, 14, FALSE) -> 0 | X11: =_xlfn.XLOOKUP(D11, OLDSURVLOOKUP!$A:$A, OLDSURVLOOKUP!X:X) -> 0 | Y11: =VLOOKUP(D11, SURVLOOKUP!$A:$Q, 15, FALSE) -> 0 | Z11: =IF(V11=0, DATEDIF(I11,P11,"M")+DATEDIF(I11,P11,"MD")/DAY(EOMONTH(I11,0)), DATEDIF(I11,R11,"M")+DATEDIF(I11,R11,"MD")/DAY(EOMONTH(I11,0))) -> 10.966667 | AA11: =IF(W11=0, DATEDIF(I11,Q11,"M")+DATEDIF(I11,Q11,"MD")/DAY(EOMONTH(I11,0)), DATEDIF(I11,S11,"M")+DATEDIF(I11,S11,"MD")/DAY(EOMONTH(I11,0))) -> 35 | AB11: =IF(X11=0, DATEDIF(I11,P11,"M")+DATEDIF(I11,P11,"MD")/DAY(EOMONTH(I11,0)), DATEDIF(I11,T11,"M")+DATEDIF(I11,T11,"MD")/DAY(EOMONTH(I11,0))) -> 10.966667 | AC11: =IF(Y11=0, DATEDIF(I11,Q11,"M")+DATEDIF(I11,Q11,"MD")/DAY(EOMONTH(I11,0)), DATEDIF(I11,U11,"M")+DATEDIF(I11,U11,"MD")/DAY(EOMONTH(I11,0))) -> 35 | AD11: =IF(V11=0, DATEDIF(J11,P11,"M")+DATEDIF(J11,P11,"MD")/DAY(EOMONTH(J11,0)), DATEDIF(J11,R11,"M")+DATEDIF(J11,R11,"MD")/DAY(EOMONTH(J11,0))) -> 10.7 | AE11: =IF(W11=0, DATEDIF(J11,Q11,"M")+DATEDIF(J11,Q11,"MD")/DAY(EOMONTH(J11,0)), DATEDIF(J11,S11,"M")+DATEDIF(J11,S11,"MD")/DAY(EOMONTH(J11,0))) -> 34.733333 | AF11: =IF(X11=0, DATEDIF(J11,P11,"M")+DATEDIF(J11,P11,"MD")/DAY(EOMONTH(J11,0)), DATEDIF(J11,T11,"M")+DATEDIF(J11,T11,"MD")/DAY(EOMONTH(J11,0))) -> 10.7 | AG11: =IF(Y11=0, DATEDIF(J11,Q11,"M")+DATEDIF(J11,Q11,"MD")/DAY(EOMONTH(J11,0)), DATEDIF(J11,U11,"M")+DATEDIF(J11,U11,"MD")/DAY(EOMONTH(J11,0))) -> 34.733333 | AL11: =IF(MID(A11,FIND("_",A11)-1,1)="2", 2, 1) -> 2 | AM11: =IFERROR( CHOOSE( VALUE(MID(D11, FIND("-", D11) - 1, 1)), "University of Cincinnati", "Ohio State University", "Medical University of South Carolina", "University of Michigan", "University of Louisville", "MD Anderson" ), "Unknown" ) -> University of Cincinnati | AN11: 0 | AO11: 4 | AP11: =(_xlfn.XLOOKUP($D11,RAWMETADATALOOKUP_P1!$A:$A,RAWMETADATALOOKUP_P1!F:F)) -> 75 | AQ11: =(_xlfn.XLOOKUP($D11,RAWMETADATALOOKUP_P1!$A:$A,RAWMETADATALOOKUP_P1!G:G)) -> Male | AR11: =(_xlfn.XLOOKUP($D11,RAWMETADATALOOKUP_P1!$A:$A,RAWMETADATALOOKUP_P1!H:H)) -> White | AS11: =(_xlfn.XLOOKUP($D11,RAWMETADATALOOKUP_P1!$A:$A,RAWMETADATALOOKUP_P1!I:I)) -> Yes | AT11: =(_xlfn.XLOOKUP($D11,RAWMETADATALOOKUP_P1!$A:$A,RAWMETADATALOOKUP_P1!J:J)) -> Non-Hispanic | AU11: =(_xlfn.XLOOKUP($D11,RAWMETADATALOOKUP_P1!$A:$A,RAWMETADATALOOKUP_P1!K:K)) -> No | AV11: =(_xlfn.XLOOKUP($D11,RAWMETADATALOOKUP_P1!$A:$A,RAWMETADATALOOKUP_P1!Q:Q)) -> T4aN0M0 | AW11: =LEFT(_xlfn.XLOOKUP(D11, RAWMETADATALOOKUP_P2!A:A,RAWMETADATALOOKUP_P2!G:G), FIND(" ", _xlfn.XLOOKUP(D11, RAWMETADATALOOKUP_P2!A:A,RAWMETADATALOOKUP_P2!G:G)&" ")-1) -> Intermediate | AX11: =(_xlfn.XLOOKUP($D11,RAWMETADATALOOKUP_P1!$A:$A,RAWMETADATALOOKUP_P1!R:R)) -> Unknown | AY11: =LOOKUP(D11, SURVLOOKUP!$A:$A, SURVLOOKUP!$P:$P) -> 1 | AZ11: 3 | BA11: 0.3 | BB11: =IF(AZ11=0, "Non-Responder", "Responder") -> Responder | BC11: 0.154 | BE11: 24 | BF11: 6.493506 | BG11: 43.50649 | BH11: 21 | BI11: 1.190476 | BJ11: UDI0265 | BK11: TATACCAT | BL11: AATGCCAC
A12: Pilot2_13 | B12: =VLOOKUP(A12, IDSLOOKUP!C:E, 2, FALSE) -> Day 0 | C12: =(_xlfn.XLOOKUP(D12,RAWMETADATALOOKUP_P1!A:A,RAWMETADATALOOKUP_P1!M:M)) -> Larynx | D12: =VLOOKUP(A12, IDSLOOKUP!C:E, 3, FALSE) -> HN01-51 | E12: =VLOOKUP(A12,CFDNALOOKUP!AG:AI,2,FALSE) -> 44090 | F12: =VLOOKUP(A12,CFDNALOOKUP!AG:AI,3,FALSE) -> 44179 | G12: =VLOOKUP(D12, SURVLOOKUP!$A:$Q, 2, FALSE) -> 43974 | H12: =VLOOKUP(D12, SURVLOOKUP!$A:$Q, 3, FALSE) -> 43997 | I12: =VLOOKUP(D12, SURVLOOKUP!$A:$Q, 4, FALSE) -> 44000 | J12: =VLOOKUP(D12, SURVLOOKUP!$A:$Q, 5, FALSE) -> 44008 | K12: =VLOOKUP(D12, SURVLOOKUP!$A:$Q, 6, FALSE) -> NA | L12: =VLOOKUP(D12, SURVLOOKUP!$A:$Q, 7, FALSE) -> NA | M12: =VLOOKUP(D12, SURVLOOKUP!$A:$Q, 8, FALSE) -> NA | N12: =VLOOKUP(D12, SURVLOOKUP!$A:$Q, 9, FALSE) -> NA | O12: =VLOOKUP(D12, SURVLOOKUP!$A:$Q, 10, FALSE) -> NA | P12: =VLOOKUP(D12, OLDSURVLOOKUP!$A:$AA, 19, FALSE) -> 44333 | Q12: =VLOOKUP(D12, SURVLOOKUP!$A:$Q, 11, FALSE) -> 45064 | V12: =_xlfn.XLOOKUP(D12, OLDSURVLOOKUP!$A:$A, OLDSURVLOOKUP!V:V) -> 0 | W12: =VLOOKUP(D12, SURVLOOKUP!$A:$Q, 14, FALSE) -> 0 | X12: =_xlfn.XLOOKUP(D12, OLDSURVLOOKUP!$A:$A, OLDSURVLOOKUP!X:X) -> 0 | Y12: =VLOOKUP(D12, SURVLOOKUP!$A:$Q, 15, FALSE) -> 0 | Z12: =IF(V12=0, DATEDIF(I12,P12,"M")+DATEDIF(I12,P12,"MD")/DAY(EOMONTH(I12,0)), DATEDIF(I12,R12,"M")+DATEDIF(I12,R12,"MD")/DAY(EOMONTH(I12,0))) -> 10.966667 | AA12: =IF(W12=0, DATEDIF(I12,Q12,"M")+DATEDIF(I12,Q12,"MD")/DAY(EOMONTH(I12,0)), DATEDIF(I12,S12,"M")+DATEDIF(I12,S12,"MD")/DAY(EOMONTH(I12,0))) -> 35 | AB12: =IF(X12=0, DATEDIF(I12,P12,"M")+DATEDIF(I12,P12,"MD")/DAY(EOMONTH(I12,0)), DATEDIF(I12,T12,"M")+DATEDIF(I12,T12,"MD")/DAY(EOMONTH(I12,0))) -> 10.966667 | AC12: =IF(Y12=0, DATEDIF(I12,Q12,"M")+DATEDIF(I12,Q12,"MD")/DAY(EOMONTH(I12,0)), DATEDIF(I12,U12,"M")+DATEDIF(I12,U12,"MD")/DAY(EOMONTH(I12,0))) -> 35 | AD12: =IF(V12=0, DATEDIF(J12,P12,"M")+DATEDIF(J12,P12,"MD")/DAY(EOMONTH(J12,0)), DATEDIF(J12,R12,"M")+DATEDIF(J12,R12,"MD")/DAY(EOMONTH(J12,0))) -> 10.7 | AE12: =IF(W12=0, DATEDIF(J12,Q12,"M")+DATEDIF(J12,Q12,"MD")/DAY(EOMONTH(J12,0)), DATEDIF(J12,S12,"M")+DATEDIF(J12,S12,"MD")/DAY(EOMONTH(J12,0))) -> 34.733333 | AF12: =IF(X12=0, DATEDIF(J12,P12,"M")+DATEDIF(J12,P12,"MD")/DAY(EOMONTH(J12,0)), DATEDIF(J12,T12,"M")+DATEDIF(J12,T12,"MD")/DAY(EOMONTH(J12,0))) -> 10.7 | AG12: =IF(Y12=0, DATEDIF(J12,Q12,"M")+DATEDIF(J12,Q12,"MD")/DAY(EOMONTH(J12,0)), DATEDIF(J12,U12,"M")+DATEDIF(J12,U12,"MD")/DAY(EOMONTH(J12,0))) -> 34.733333 | AL12: =IF(MID(A12,FIND("_",A12)-1,1)="2", 2, 1) -> 2 | AM12: =IFERROR( CHOOSE( VALUE(MID(D12, FIND("-", D12) - 1, 1)), "University of Cincinnati", "Ohio State University", "Medical University of South Carolina", "University of Michigan", "University of Louisville", "MD Anderson" ), "Unknown" ) -> University of Cincinnati | AN12: 0 | AO12: 4 | AP12: =(_xlfn.XLOOKUP($D12,RAWMETADATALOOKUP_P1!$A:$A,RAWMETADATALOOKUP_P1!F:F)) -> 75 | AQ12: =(_xlfn.XLOOKUP($D12,RAWMETADATALOOKUP_P1!$A:$A,RAWMETADATALOOKUP_P1!G:G)) -> Male | AR12: =(_xlfn.XLOOKUP($D12,RAWMETADATALOOKUP_P1!$A:$A,RAWMETADATALOOKUP_P1!H:H)) -> White | AS12: =(_xlfn.XLOOKUP($D12,RAWMETADATALOOKUP_P1!$A:$A,RAWMETADATALOOKUP_P1!I:I)) -> Yes | AT12: =(_xlfn.XLOOKUP($D12,RAWMETADATALOOKUP_P1!$A:$A,RAWMETADATALOOKUP_P1!J:J)) -> Non-Hispanic | AU12: =(_xlfn.XLOOKUP($D12,RAWMETADATALOOKUP_P1!$A:$A,RAWMETADATALOOKUP_P1!K:K)) -> No | AV12: =(_xlfn.XLOOKUP($D12,RAWMETADATALOOKUP_P1!$A:$A,RAWMETADATALOOKUP_P1!Q:Q)) -> T4aN0M0 | AW12: =LEFT(_xlfn.XLOOKUP(D12, RAWMETADATALOOKUP_P2!A:A,RAWMETADATALOOKUP_P2!G:G), FIND(" ", _xlfn.XLOOKUP(D12, RAWMETADATALOOKUP_P2!A:A,RAWMETADATALOOKUP_P2!G:G)&" ")-1) -> Intermediate | AX12: =(_xlfn.XLOOKUP($D12,RAWMETADATALOOKUP_P1!$A:$A,RAWMETADATALOOKUP_P1!R:R)) -> Unknown | AY12: =LOOKUP(D12, SURVLOOKUP!$A:$A, SURVLOOKUP!$P:$P) -> 1 | AZ12: 3 | BA12: 0.3 | BB12: =IF(AZ12=0, "Non-Responder", "Responder") -> Responder | BC12: 0.212 | BE12: 24 | BF12: 4.716981 | BG12: 45.28302 | BH12: 18.5 | BI12: 1.351351 | BJ12: UDI0278 | BK12: ATCGTTAG | BL12: TGCGAAGT
A13: Pilot2_14 | B13: =VLOOKUP(A13, IDSLOOKUP!C:E, 2, FALSE) -> Screen | C13: =VLOOKUP(D13, METADATALOOKUP!$A:$AI, 13, FALSE) -> Oral Cavity | D13: =VLOOKUP(A13, IDSLOOKUP!C:E, 3, FALSE) -> HN02-01 | E13: =VLOOKUP(A13,CFDNALOOKUP!AG:AI,2,FALSE) -> 44090 | F13: =VLOOKUP(A13,CFDNALOOKUP!AG:AI,3,FALSE) -> 44180 | G13: =VLOOKUP(D13, SURVLOOKUP!$A:$Q, 2, FALSE) -> 42774 | H13: =VLOOKUP(D13, SURVLOOKUP!$A:$Q, 3, FALSE) -> 42900 | I13: =VLOOKUP(D13, SURVLOOKUP!$A:$Q, 4, FALSE) -> 42908 | J13: =VLOOKUP(D13, SURVLOOKUP!$A:$Q, 5, FALSE) -> 42921 | K13: =VLOOKUP(D13, SURVLOOKUP!$A:$Q, 6, FALSE) -> 42962 | L13: =VLOOKUP(D13, SURVLOOKUP!$A:$Q, 7, FALSE) -> 43004 | M13: =VLOOKUP(D13, SURVLOOKUP!$A:$Q, 8, FALSE) -> 42955 | N13: =VLOOKUP(D13, SURVLOOKUP!$A:$Q, 9, FALSE) -> 43060 | O13: =VLOOKUP(D13, SURVLOOKUP!$A:$Q, 10, FALSE) -> NA | P13: =VLOOKUP(D13, OLDSURVLOOKUP!$A:$AA, 19, FALSE) -> 43625 | Q13: =VLOOKUP(D13, SURVLOOKUP!$A:$Q, 11, FALSE) -> 43625 | R13: =VLOOKUP(D13, OLDSURVLOOKUP!$A:$AA, 20, FALSE) -> 43220 | S13: =VLOOKUP(D13, SURVLOOKUP!$A:$Q, 12, FALSE) -> 43220 | T13: =VLOOKUP(D13, OLDSURVLOOKUP!$A:$AA, 21, FALSE) -> 43626 | U13: =VLOOKUP(D13, SURVLOOKUP!$A:$Q, 13, FALSE) -> 43626 | V13: =_xlfn.XLOOKUP(D13, OLDSURVLOOKUP!$A:$A, OLDSURVLOOKUP!V:V) -> 1 | W13: =VLOOKUP(D13, SURVLOOKUP!$A:$Q, 14, FALSE) -> 1 | X13: =_xlfn.XLOOKUP(D13, OLDSURVLOOKUP!$A:$A, OLDSURVLOOKUP!X:X) -> 1 | Y13: =VLOOKUP(D13, SURVLOOKUP!$A:$Q, 15, FALSE) -> 1 | Z13: =IF(V13=0, DATEDIF(I13,P13,"M")+DATEDIF(I13,P13,"MD")/DAY(EOMONTH(I13,0)), DATEDIF(I13,R13,"M")+DATEDIF(I13,R13,"MD")/DAY(EOMONTH(I13,0))) -> 10.266667 | AA13: =IF(W13=0, DATEDIF(I13,Q13,"M")+DATEDIF(I13,Q13,"MD")/DAY(EOMONTH(I13,0)), DATEDIF(I13,S13,"M")+DATEDIF(I13,S13,"MD")/DAY(EOMONTH(I13,0))) -> 10.266667 | AB13: =IF(X13=0, DATEDIF(I13,P13,"M")+DATEDIF(I13,P13,"MD")/DAY(EOMONTH(I13,0)), DATEDIF(I13,T13,"M")+DATEDIF(I13,T13,"MD")/DAY(EOMONTH(I13,0))) -> 23.633333 | AC13: =IF(Y13=0, DATEDIF(I13,Q13,"M")+DATEDIF(I13,Q13,"MD")/DAY(EOMONTH(I13,0)), DATEDIF(I13,U13,"M")+DATEDIF(I13,U13,"MD")/DAY(EOMONTH(I13,0))) -> 23.633333 | AD13: =IF(V13=0, DATEDIF(J13,P13,"M")+DATEDIF(J13,P13,"MD")/DAY(EOMONTH(J13,0)), DATEDIF(J13,R13,"M")+DATEDIF(J13,R13,"MD")/DAY(EOMONTH(J13,0))) -> 9.8064516 | AE13: =IF(W13=0, DATEDIF(J13,Q13,"M")+DATEDIF(J13,Q13,"MD")/DAY(EOMONTH(J13,0)), DATEDIF(J13,S13,"M")+DATEDIF(J13,S13,"MD")/DAY(EOMONTH(J13,0))) -> 9.8064516 | AF13: =IF(X13=0, DATEDIF(J13,P13,"M")+DATEDIF(J13,P13,"MD")/DAY(EOMONTH(J13,0)), DATEDIF(J13,T13,"M")+DATEDIF(J13,T13,"MD")/DAY(EOMONTH(J13,0))) -> 23.16129 | AG13: =IF(Y13=0, DATEDIF(J13,Q13,"M")+DATEDIF(J13,Q13,"MD")/DAY(EOMONTH(J13,0)), DATEDIF(J13,U13,"M")+DATEDIF(J13,U13,"MD")/DAY(EOMONTH(J13,0))) -> 23.16129 | AH13: =IF(V13=0, DATEDIF(M13,P13,"M")+DATEDIF(M13,P13,"MD")/DAY(EOMONTH(M13,0)), DATEDIF(M13,R13,"M")+DATEDIF(M13,R13,"MD")/DAY(EOMONTH(M13,0))) -> 8.7096774 | AI13: =IF(W13=0, DATEDIF(M13,Q13,"M")+DATEDIF(M13,Q13,"MD")/DAY(EOMONTH(M13,0)), DATEDIF(M13,S13,"M")+DATEDIF(M13,S13,"MD")/DAY(EOMONTH(M13,0))) -> 8.7096774 | AJ13: =IF(X13=0, DATEDIF(M13,P13,"M")+DATEDIF(M13,P13,"MD")/DAY(EOMONTH(M13,0)), DATEDIF(M13,T13,"M")+DATEDIF(M13,T13,"MD")/DAY(EOMONTH(M13,0))) -> 22.064516 | AK13: =IF(Y13=0, DATEDIF(M13,Q13,"M")+DATEDIF(M13,Q13,"MD")/DAY(EOMONTH(M13,0)), DATEDIF(M13,U13,"M")+DATEDIF(M13,U13,"MD")/DAY(EOMONTH(M13,0))) -> 22.064516 | AL13: =IF(MID(A13,FIND("_",A13)-1,1)="2", 2, 1) -> 2 | AM13: =IFERROR( CHOOSE( VALUE(MID(D13, FIND("-", D13) - 1, 1)), "University of Cincinnati", "Ohio State University", "Medical University of South Carolina", "University of Michigan", "University of Louisville", "MD Anderson" ), "Unknown" ) -> Ohio State University | AN13: 0 | AO13: 5 | AP13: =VLOOKUP(D13, METADATALOOKUP!$A:$AI, 7, FALSE) -> 70 | AQ13: =VLOOKUP(D13, METADATALOOKUP!$A:$AI, 8, FALSE) -> Female | AR13: =VLOOKUP(D13, METADATALOOKUP!$A:$AI, 9, FALSE) -> White | AS13: =VLOOKUP(D13, METADATALOOKUP!$A:$AI, 11, FALSE) -> No | AT13: =VLOOKUP(D13, METADATALOOKUP!$A:$AI, 10, FALSE) -> Non-Hispanic | AU13: =VLOOKUP(D13, METADATALOOKUP!$A:$AI, 12, FALSE) -> No | AV13: =VLOOKUP(D13, METADATALOOKUP!$A:$AI, 14, FALSE) -> cT4N2bM0 | AW13: =VLOOKUP(D13, METADATALOOKUP!$A:$AI, 6, FALSE) -> High | AX13: =VLOOKUP(D13, METADATALOOKUP!$A:$AI, 19, FALSE) -> Unknown | AY13: =LOOKUP(D13, SURVLOOKUP!$A:$A, SURVLOOKUP!$P:$P) -> 1 | AZ13: 0 | BA13: =TEXT(VLOOKUP(D13, METADATALOOKUP!$A:$AI, 34, FALSE), "@") -> <10% | BB13: =IF(AZ13=0, "Non-Responder", "Responder") -> Non-Responder | BC13: 0.21 | BE13: 24 | BF13: 4.761905 | BG13: 45.2381 | BH13: 14 | BI13: 1.785714 | BJ13: UDI0278 | BK13: ATCGTTAG | BL13: TGCGAAGT
A14: Pilot2_15 | B14: =VLOOKUP(A14, IDSLOOKUP!C:E, 2, FALSE) -> Day 0 | C14: =VLOOKUP(D14, METADATALOOKUP!$A:$AI, 13, FALSE) -> Oral Cavity | D14: =VLOOKUP(A14, IDSLOOKUP!C:E, 3, FALSE) -> HN02-01 | E14: =VLOOKUP(A14,CFDNALOOKUP!AG:AI,2,FALSE) -> 44090 | F14: =VLOOKUP(A14,CFDNALOOKUP!AG:AI,3,FALSE) -> 44179 | G14: =VLOOKUP(D14, SURVLOOKUP!$A:$Q, 2, FALSE) -> 42774 | H14: =VLOOKUP(D14, SURVLOOKUP!$A:$Q, 3, FALSE) -> 42900 | I14: =VLOOKUP(D14, SURVLOOKUP!$A:$Q, 4, FALSE) -> 42908 | J14: =VLOOKUP(D14, SURVLOOKUP!$A:$Q, 5, FALSE) -> 42921 | K14: =VLOOKUP(D14, SURVLOOKUP!$A:$Q, 6, FALSE) -> 42962 | L14: =VLOOKUP(D14, SURVLOOKUP!$A:$Q, 7, FALSE) -> 43004 | M14: =VLOOKUP(D14, SURVLOOKUP!$A:$Q, 8, FALSE) -> 42955 | N14: =VLOOKUP(D14, SURVLOOKUP!$A:$Q, 9, FALSE) -> 43060 | O14: =VLOOKUP(D14, SURVLOOKUP!$A:$Q, 10, FALSE) -> NA | P14: =VLOOKUP(D14, OLDSURVLOOKUP!$A:$AA, 19, FALSE) -> 43625 | Q14: =VLOOKUP(D14, SURVLOOKUP!$A:$Q, 11, FALSE) -> 43625 | R14: =VLOOKUP(D14, OLDSURVLOOKUP!$A:$AA, 20, FALSE) -> 43220 | S14: =VLOOKUP(D14, SURVLOOKUP!$A:$Q, 12, FALSE) -> 43220 | T14: =VLOOKUP(D14, OLDSURVLOOKUP!$A:$AA, 21, FALSE) -> 43626 | U14: =VLOOKUP(D14, SURVLOOKUP!$A:$Q, 13, FALSE) -> 43626 | V14: =_xlfn.XLOOKUP(D14, OLDSURVLOOKUP!$A:$A, OLDSURVLOOKUP!V:V) -> 1 | W14: =VLOOKUP(D14, SURVLOOKUP!$A:$Q, 14, FALSE) -> 1 | X14: =_xlfn.XLOOKUP(D14, OLDSURVLOOKUP!$A:$A, OLDSURVLOOKUP!X:X) -> 1 | Y14: =VLOOKUP(D14, SURVLOOKUP!$A:$Q, 15, FALSE) -> 1 | Z14: =IF(V14=0, DATEDIF(I14,P14,"M")+DATEDIF(I14,P14,"MD")/DAY(EOMONTH(I14,0)), DATEDIF(I14,R14,"M")+DATEDIF(I14,R14,"MD")/DAY(EOMONTH(I14,0))) -> 10.266667 | AA14: =IF(W14=0, DATEDIF(I14,Q14,"M")+DATEDIF(I14,Q14,"MD")/DAY(EOMONTH(I14,0)), DATEDIF(I14,S14,"M")+DATEDIF(I14,S14,"MD")/DAY(EOMONTH(I14,0))) -> 10.266667 | AB14: =IF(X14=0, DATEDIF(I14,P14,"M")+DATEDIF(I14,P14,"MD")/DAY(EOMONTH(I14,0)), DATEDIF(I14,T14,"M")+DATEDIF(I14,T14,"MD")/DAY(EOMONTH(I14,0))) -> 23.633333 | AC14: =IF(Y14=0, DATEDIF(I14,Q14,"M")+DATEDIF(I14,Q14,"MD")/DAY(EOMONTH(I14,0)), DATEDIF(I14,U14,"M")+DATEDIF(I14,U14,"MD")/DAY(EOMONTH(I14,0))) -> 23.633333 | AD14: =IF(V14=0, DATEDIF(J14,P14,"M")+DATEDIF(J14,P14,"MD")/DAY(EOMONTH(J14,0)), DATEDIF(J14,R14,"M")+DATEDIF(J14,R14,"MD")/DAY(EOMONTH(J14,0))) -> 9.8064516 | AE14: =IF(W14=0, DATEDIF(J14,Q14,"M")+DATEDIF(J14,Q14,"MD")/DAY(EOMONTH(J14,0)), DATEDIF(J14,S14,"M")+DATEDIF(J14,S14,"MD")/DAY(EOMONTH(J14,0))) -> 9.8064516 | AF14: =IF(X14=0, DATEDIF(J14,P14,"M")+DATEDIF(J14,P14,"MD")/DAY(EOMONTH(J14,0)), DATEDIF(J14,T14,"M")+DATEDIF(J14,T14,"MD")/DAY(EOMONTH(J14,0))) -> 23.16129 | AG14: =IF(Y14=0, DATEDIF(J14,Q14,"M")+DATEDIF(J14,Q14,"MD")/DAY(EOMONTH(J14,0)), DATEDIF(J14,U14,"M")+DATEDIF(J14,U14,"MD")/DAY(EOMONTH(J14,0))) -> 23.16129 | AH14: =IF(V14=0, DATEDIF(M14,P14,"M")+DATEDIF(M14,P14,"MD")/DAY(EOMONTH(M14,0)), DATEDIF(M14,R14,"M")+DATEDIF(M14,R14,"MD")/DAY(EOMONTH(M14,0))) -> 8.7096774 | AI14: =IF(W14=0, DATEDIF(M14,Q14,"M")+DATEDIF(M14,Q14,"MD")/DAY(EOMONTH(M14,0)), DATEDIF(M14,S14,"M")+DATEDIF(M14,S14,"MD")/DAY(EOMONTH(M14,0))) -> 8.7096774 | AJ14: =IF(X14=0, DATEDIF(M14,P14,"M")+DATEDIF(M14,P14,"MD")/DAY(EOMONTH(M14,0)), DATEDIF(M14,T14,"M")+DATEDIF(M14,T14,"MD")/DAY(EOMONTH(M14,0))) -> 22.064516 | AK14: =IF(Y14=0, DATEDIF(M14,Q14,"M")+DATEDIF(M14,Q14,"MD")/DAY(EOMONTH(M14,0)), DATEDIF(M14,U14,"M")+DATEDIF(M14,U14,"MD")/DAY(EOMONTH(M14,0))) -> 22.064516 | AL14: =IF(MID(A14,FIND("_",A14)-1,1)="2", 2, 1) -> 2 | AM14: =IFERROR( CHOOSE( VALUE(MID(D14, FIND("-", D14) - 1, 1)), "University of Cincinnati", "Ohio State University", "Medical University of South Carolina", "University of Michigan", "University of Louisville", "MD Anderson" ), "Unknown" ) -> Ohio State University | AN14: 0 | AO14: 5 | AP14: =VLOOKUP(D14, METADATALOOKUP!$A:$AI, 7, FALSE) -> 70 | AQ14: =VLOOKUP(D14, METADATALOOKUP!$A:$AI, 8, FALSE) -> Female | AR14: =VLOOKUP(D14, METADATALOOKUP!$A:$AI, 9, FALSE) -> White | AS14: =VLOOKUP(D14, METADATALOOKUP!$A:$AI, 11, FALSE) -> No | AT14: =VLOOKUP(D14, METADATALOOKUP!$A:$AI, 10, FALSE) -> Non-Hispanic | AU14: =VLOOKUP(D14, METADATALOOKUP!$A:$AI, 12, FALSE) -> No | AV14: =VLOOKUP(D14, METADATALOOKUP!$A:$AI, 14, FALSE) -> cT4N2bM0 | AW14: =VLOOKUP(D14, METADATALOOKUP!$A:$AI, 6, FALSE) -> High | AX14: =VLOOKUP(D14, METADATALOOKUP!$A:$AI, 19, FALSE) -> Unknown | AY14: =LOOKUP(D14, SURVLOOKUP!$A:$A, SURVLOOKUP!$P:$P) -> 1 | AZ14: 0 | BA14: =TEXT(VLOOKUP(D14, METADATALOOKUP!$A:$AI, 34, FALSE), "@") -> <10% | BB14: =IF(AZ14=0, "Non-Responder", "Responder") -> Non-Responder | BC14: 0.416 | BE14: 24 | BF14: 2.403846 | BG14: 47.59615 | BH14: 14.9 | BI14: 1.677852 | BJ14: UDI0208 | BK14: TTGCCTCT | BL14: TGCGGCTA
